Workbook

Sheet 概要
A2: リアル系アクションゲームの製品アートレビュー
A4: プロジェクト | B4: メタルギア ライジング リベンジェンス リメイク（仮称） | E4: Build
A5: 評価日 | E5: 評価者
A6: 目標FPS | B6: 60 | E6: 出力／再構成
A8: ビジュアル総合スコア | B8: =IF(AND(B10=60,F10=60),ROUND(SUM('採点入力'!H6:H65),6),"") | E8: スコア帯別ランク | F8: =IF(ISNUMBER(B8),LOOKUP(B8,'使用方法'!$A$23:$A$27,'使用方法'!$B$23:$B$27),"")
A9: 評価状況 | B9: =IF(B10<60,"採点未完了",IF(F10<60,"根拠資料未完備","採点・根拠資料完備")) -> 採点未完了 | E9: パフォーマンス・操作応答 | F9: 未検証
A10: 採点完了 | B10: =SUM('採点入力'!P6:P65) -> 0 | E10: 根拠資料の充足 | F10: =SUM('採点入力'!Q6:Q65) -> 0
A11: 採点カバー率 | B11: =SUMPRODUCT('採点入力'!D6:D65,'採点入力'!P6:P65)/100 -> 0 | E11: 根拠資料カバー率 | F11: =SUMPRODUCT('採点入力'!D6:D65,'採点入力'!Q6:Q65)/100 -> 0
A13: 評価カテゴリ | B13: レビュー対象 | C13: 配点比率 | D13: 採点完了 | E13: 根拠資料の充足 | F13: カテゴリ別スコア／5 | G13: 加重点 | H13: 4点までの差
A14: A | B14: ビジュアルデザイン全般 | C14: 6 | D14: =SUMIFS('採点入力'!$P$6:$P$65,'採点入力'!$B$6:$B$65,B14) -> 0 | E14: =SUMIFS('採点入力'!$Q$6:$Q$65,'採点入力'!$B$6:$B$65,B14) -> 0 | F14: =IF(D14=5,ROUND(SUMIFS('採点入力'!$H$6:$H$65,'採点入力'!$B$6:$B$65,B14)/C14*5,6),"") | G14: =IF(D14=5,SUMIFS('採点入力'!$H$6:$H$65,'採点入力'!$B$6:$B$65,B14),"") | H14: =IF(ISNUMBER(F14),MAX(0,(4-F14)/5*C14),"")
A15: B | B15: シーンとジオメトリ | C15: 12 | D15: =SUMIFS('採点入力'!$P$6:$P$65,'採点入力'!$B$6:$B$65,B15) -> 0 | E15: =SUMIFS('採点入力'!$Q$6:$Q$65,'採点入力'!$B$6:$B$65,B15) -> 0 | F15: =IF(D15=5,ROUND(SUMIFS('採点入力'!$H$6:$H$65,'採点入力'!$B$6:$B$65,B15)/C15*5,6),"") | G15: =IF(D15=5,SUMIFS('採点入力'!$H$6:$H$65,'採点入力'!$B$6:$B$65,B15),"") | H15: =IF(ISNUMBER(F15),MAX(0,(4-F15)/5*C15),"")
A16: C | B16: マテリアルとテクスチャ | C16: 10 | D16: =SUMIFS('採点入力'!$P$6:$P$65,'採点入力'!$B$6:$B$65,B16) -> 0 | E16: =SUMIFS('採点入力'!$Q$6:$Q$65,'採点入力'!$B$6:$B$65,B16) -> 0 | F16: =IF(D16=5,ROUND(SUMIFS('採点入力'!$H$6:$H$65,'採点入力'!$B$6:$B$65,B16)/C16*5,6),"") | G16: =IF(D16=5,SUMIFS('採点入力'!$H$6:$H$65,'採点入力'!$B$6:$B$65,B16),"") | H16: =IF(ISNUMBER(F16),MAX(0,(4-F16)/5*C16),"")
A17: D | B17: ライティングと間接光 | C17: 14 | D17: =SUMIFS('採点入力'!$P$6:$P$65,'採点入力'!$B$6:$B$65,B17) -> 0 | E17: =SUMIFS('採点入力'!$Q$6:$Q$65,'採点入力'!$B$6:$B$65,B17) -> 0 | F17: =IF(D17=5,ROUND(SUMIFS('採点入力'!$H$6:$H$65,'採点入力'!$B$6:$B$65,B17)/C17*5,6),"") | G17: =IF(D17=5,SUMIFS('採点入力'!$H$6:$H$65,'採点入力'!$B$6:$B$65,B17),"") | H17: =IF(ISNUMBER(F17),MAX(0,(4-F17)/5*C17),"")
A18: E | B18: シャドウと接触表現 | C18: 8 | D18: =SUMIFS('採点入力'!$P$6:$P$65,'採点入力'!$B$6:$B$65,B18) -> 0 | E18: =SUMIFS('採点入力'!$Q$6:$Q$65,'採点入力'!$B$6:$B$65,B18) -> 0 | F18: =IF(D18=5,ROUND(SUMIFS('採点入力'!$H$6:$H$65,'採点入力'!$B$6:$B$65,B18)/C18*5,6),"") | G18: =IF(D18=5,SUMIFS('採点入力'!$H$6:$H$65,'採点入力'!$B$6:$B$65,B18),"") | H18: =IF(ISNUMBER(F18),MAX(0,(4-F18)/5*C18),"")
A19: F | B19: 反射と環境ライティングの入力データ | C19: 6 | D19: =SUMIFS('採点入力'!$P$6:$P$65,'採点入力'!$B$6:$B$65,B19) -> 0 | E19: =SUMIFS('採点入力'!$Q$6:$Q$65,'採点入力'!$B$6:$B$65,B19) -> 0 | F19: =IF(D19=5,ROUND(SUMIFS('採点入力'!$H$6:$H$65,'採点入力'!$B$6:$B$65,B19)/C19*5,6),"") | G19: =IF(D19=5,SUMIFS('採点入力'!$H$6:$H$65,'採点入力'!$B$6:$B$65,B19),"") | H19: =IF(ISNUMBER(F19),MAX(0,(4-F19)/5*C19),"")
A20: G | B20: 大気表現とフォグ | C20: 5 | D20: =SUMIFS('採点入力'!$P$6:$P$65,'採点入力'!$B$6:$B$65,B20) -> 0 | E20: =SUMIFS('採点入力'!$Q$6:$Q$65,'採点入力'!$B$6:$B$65,B20) -> 0 | F20: =IF(D20=5,ROUND(SUMIFS('採点入力'!$H$6:$H$65,'採点入力'!$B$6:$B$65,B20)/C20*5,6),"") | G20: =IF(D20=5,SUMIFS('採点入力'!$H$6:$H$65,'採点入力'!$B$6:$B$65,B20),"") | H20: =IF(ISNUMBER(F20),MAX(0,(4-F20)/5*C20),"")
A21: H | B21: キャラクターとアニメーション表現 | C21: 10 | D21: =SUMIFS('採点入力'!$P$6:$P$65,'採点入力'!$B$6:$B$65,B21) -> 0 | E21: =SUMIFS('採点入力'!$Q$6:$Q$65,'採点入力'!$B$6:$B$65,B21) -> 0 | F21: =IF(D21=5,ROUND(SUMIFS('採点入力'!$H$6:$H$65,'採点入力'!$B$6:$B$65,B21)/C21*5,6),"") | G21: =IF(D21=5,SUMIFS('採点入力'!$H$6:$H$65,'採点入力'!$B$6:$B$65,B21),"") | H21: =IF(ISNUMBER(F21),MAX(0,(4-F21)/5*C21),"")
A22: I | B22: エフェクトと戦闘フィードバック | C22: 8 | D22: =SUMIFS('採点入力'!$P$6:$P$65,'採点入力'!$B$6:$B$65,B22) -> 0 | E22: =SUMIFS('採点入力'!$Q$6:$Q$65,'採点入力'!$B$6:$B$65,B22) -> 0 | F22: =IF(D22=5,ROUND(SUMIFS('採点入力'!$H$6:$H$65,'採点入力'!$B$6:$B$65,B22)/C22*5,6),"") | G22: =IF(D22=5,SUMIFS('採点入力'!$H$6:$H$65,'採点入力'!$B$6:$B$65,B22),"") | H22: =IF(ISNUMBER(F22),MAX(0,(4-F22)/5*C22),"")
A23: J | B23: 動きのある場面の画質と再構成 | C23: 10 | D23: =SUMIFS('採点入力'!$P$6:$P$65,'採点入力'!$B$6:$B$65,B23) -> 0 | E23: =SUMIFS('採点入力'!$Q$6:$Q$65,'採点入力'!$B$6:$B$65,B23) -> 0 | F23: =IF(D23=5,ROUND(SUMIFS('採点入力'!$H$6:$H$65,'採点入力'!$B$6:$B$65,B23)/C23*5,6),"") | G23: =IF(D23=5,SUMIFS('採点入力'!$H$6:$H$65,'採点入力'!$B$6:$B$65,B23),"") | H23: =IF(ISNUMBER(F23),MAX(0,(4-F23)/5*C23),"")
A24: K | B24: ポストプロセスと表示 | C24: 6 | D24: =SUMIFS('採点入力'!$P$6:$P$65,'採点入力'!$B$6:$B$65,B24) -> 0 | E24: =SUMIFS('採点入力'!$Q$6:$Q$65,'採点入力'!$B$6:$B$65,B24) -> 0 | F24: =IF(D24=5,ROUND(SUMIFS('採点入力'!$H$6:$H$65,'採点入力'!$B$6:$B$65,B24)/C24*5,6),"") | G24: =IF(D24=5,SUMIFS('採点入力'!$H$6:$H$65,'採点入力'!$B$6:$B$65,B24),"") | H24: =IF(ISNUMBER(F24),MAX(0,(4-F24)/5*C24),"")
A25: L | B25: ゲーム全編の一貫性 | C25: 5 | D25: =SUMIFS('採点入力'!$P$6:$P$65,'採点入力'!$B$6:$B$65,B25) -> 0 | E25: =SUMIFS('採点入力'!$Q$6:$Q$65,'採点入力'!$B$6:$B$65,B25) -> 0 | F25: =IF(D25=5,ROUND(SUMIFS('採点入力'!$H$6:$H$65,'採点入力'!$B$6:$B$65,B25)/C25*5,6),"") | G25: =IF(D25=5,SUMIFS('採点入力'!$H$6:$H$65,'採点入力'!$B$6:$B$65,B25),"") | H25: =IF(ISNUMBER(F25),MAX(0,(4-F25)/5*C25),"")
A26: 合計 | C26: 100 | D26: =B10 -> 0 | E26: =F10 -> 0 | G26: =IF(ISNUMBER(B8),B8,"")
A28: プラットフォーム | B28: 標準PS5 | E28: 重大な不具合の審査 | F28: 未検証
A29: 製品の受入判定 | B29: =IF(OR(F9="不合格",F28="不合格"),"不合格",IF(F29="未評価","未評価",IF(F29="最低基準未達","不合格",IF(AND(F9="合格",F28="合格"),"合格","未検証")))) -> 未評価 | E29: ビジュアルの最低品質基準 | F29: {=IF(NOT(ISNUMBER(B8)),"未評価",IF(AND(B8>=80,F17>=4,F23>=4,F15>=3.5,F16>=3.5,F18>=3.5,F21>=3.5,INDEX('採点入力'!$F$6:$F$65,MATCH("I1",'採点入力'!$A$6:$A$65,0))>=4,MIN('採点入力'!G6:G65)>=3),"最低基準達成","最低基準未達"))} -> 未評価
A31: トップ水準の認定 | B31: =IF(NOT(ISNUMBER(B8)),"未評価",IF(B8<90,"90点未満",IF(MIN(F14:F25)<4,"カテゴリ最低基準未達",IF(B29="合格","トップ水準の推奨基準を満たす",IF(B29="不合格","受入不合格","審査待ち"))))) -> 未評価
A33: 30／40／60 FPSはモード別に評価。画質と性能は別評価とし、受入には画質の最低基準と選択モードの性能要件の両方を満たすこと。
A35: 黄色は入力欄。総合スコアの空欄は資料不足を示す。各カテゴリ5項目を等配点とし、全項目の満点時の加重点は合計100点。
A37: 高品質の最低基準：D／J≧4、B／C／E／H≧3.5、I1の高負荷シーンのスコア≧4、全項目の統合スコア≧3、かつビジュアル総合スコア≧80。
A39: ランクは社内推奨基準。同一ビルドの実機比較で基準を調整し、30／40／60 FPSと操作応答の条件は関係者で合意のうえ確定する。
A41: 改善計画による加点 | B41: =IF(COUNT('採点入力'!R6:R65)=0,"",SUM('採点入力'!R6:R65)) | E41: 目標達成時の試算スコア | F41: =IF(AND(ISNUMBER(B8),ISNUMBER(B41)),B8+B41,"")
A43: 「採点入力」O列の目標値で改善による加点を試算。該当モードで再測定して達成を確認し、試算値そのものは受入の根拠にしない。

Sheet 採点入力
A2: 採点入力
A4: 黄色のセルが入力欄。通常シーンと高負荷シーンはいずれも0～5点で採点する。0点は実際の不合格、空欄は未評価を表す。両方のスコアが有効な場合のみ統合スコアを計算する。
A5: 番号 | B5: 評価カテゴリ | C5: 評価項目 | D5: 満点時の加重点 | E5: 通常シーンのスコア | F5: 高負荷シーンのスコア | G5: 統合スコア／5 | H5: 獲得加重点 | I5: 両シーンの確認 | J5: 通常シーンの根拠資料 | K5: 高負荷シーンの根拠資料 | L5: ビルド／カメラ位置 | M5: 不具合と修正内容 | N5: 担当者 | O5: 目標スコア／5 | P5: 採点の充足 | Q5: 根拠資料の充足 | R5: 目標達成による加点
A6: A1 | B6: ビジュアルデザイン全般 | C6: ビジュアル表現の統一 | D6: {=INDEX('60項目の基準'!$D$6:$D$65,MATCH(A6,'60項目の基準'!$A$6:$A$65,0))} -> 1.2 | G6: =IF(P6=1,ROUND(E6*'使用方法'!$B$5+F6*'使用方法'!$B$6,6),"") | H6: =IF(P6=1,G6/5*D6,"") | P6: =IF(COUNT(E6:F6)<>2,0,IF(AND(MIN(E6:F6)>=0,MAX(E6:F6)<=5),1,0)) -> 0 | Q6: =IF(AND(I6="確認済み",J6<>"",K6<>"",L6<>""),1,0) -> 0 | R6: =IF(AND(P6=1,ISNUMBER(O6),O6>=0,O6<=5),(O6-G6)/5*D6,"")
A7: A2 | B7: ビジュアルデザイン全般 | C7: 構図と視覚的な優先順位 | D7: {=INDEX('60項目の基準'!$D$6:$D$65,MATCH(A7,'60項目の基準'!$A$6:$A$65,0))} -> 1.2 | G7: =IF(P7=1,ROUND(E7*'使用方法'!$B$5+F7*'使用方法'!$B$6,6),"") | H7: =IF(P7=1,G7/5*D7,"") | P7: =IF(COUNT(E7:F7)<>2,0,IF(AND(MIN(E7:F7)>=0,MAX(E7:F7)<=5),1,0)) -> 0 | Q7: =IF(AND(I7="確認済み",J7<>"",K7<>"",L7<>""),1,0) -> 0 | R7: =IF(AND(P7=1,ISNUMBER(O7),O7>=0,O7<=5),(O7-G7)/5*D7,"")
A8: A3 | B8: ビジュアルデザイン全般 | C8: 空間とランドマーク | D8: {=INDEX('60項目の基準'!$D$6:$D$65,MATCH(A8,'60項目の基準'!$A$6:$A$65,0))} -> 1.2 | G8: =IF(P8=1,ROUND(E8*'使用方法'!$B$5+F8*'使用方法'!$B$6,6),"") | H8: =IF(P8=1,G8/5*D8,"") | P8: =IF(COUNT(E8:F8)<>2,0,IF(AND(MIN(E8:F8)>=0,MAX(E8:F8)<=5),1,0)) -> 0 | Q8: =IF(AND(I8="確認済み",J8<>"",K8<>"",L8<>""),1,0) -> 0 | R8: =IF(AND(P8=1,ISNUMBER(O8),O8>=0,O8<=5),(O8-G8)/5*D8,"")
A9: A4 | B9: ビジュアルデザイン全般 | C9: 色彩と明暗の設計 | D9: {=INDEX('60項目の基準'!$D$6:$D$65,MATCH(A9,'60項目の基準'!$A$6:$A$65,0))} -> 1.2 | G9: =IF(P9=1,ROUND(E9*'使用方法'!$B$5+F9*'使用方法'!$B$6,6),"") | H9: =IF(P9=1,G9/5*D9,"") | P9: =IF(COUNT(E9:F9)<>2,0,IF(AND(MIN(E9:F9)>=0,MAX(E9:F9)<=5),1,0)) -> 0 | Q9: =IF(AND(I9="確認済み",J9<>"",K9<>"",L9<>""),1,0) -> 0 | R9: =IF(AND(P9=1,ISNUMBER(O9),O9>=0,O9<=5),(O9-G9)/5*D9,"")
A10: A5 | B10: ビジュアルデザイン全般 | C10: リメイクにおける現代的な表現 | D10: {=INDEX('60項目の基準'!$D$6:$D$65,MATCH(A10,'60項目の基準'!$A$6:$A$65,0))} -> 1.2 | G10: =IF(P10=1,ROUND(E10*'使用方法'!$B$5+F10*'使用方法'!$B$6,6),"") | H10: =IF(P10=1,G10/5*D10,"") | P10: =IF(COUNT(E10:F10)<>2,0,IF(AND(MIN(E10:F10)>=0,MAX(E10:F10)<=5),1,0)) -> 0 | Q10: =IF(AND(I10="確認済み",J10<>"",K10<>"",L10<>""),1,0) -> 0 | R10: =IF(AND(P10=1,ISNUMBER(O10),O10>=0,O10<=5),(O10-G10)/5*D10,"")
A11: B1 | B11: シーンとジオメトリ | C11: スケールとシルエット | D11: {=INDEX('60項目の基準'!$D$6:$D$65,MATCH(A11,'60項目の基準'!$A$6:$A$65,0))} -> 2.4 | G11: =IF(P11=1,ROUND(E11*'使用方法'!$B$5+F11*'使用方法'!$B$6,6),"") | H11: =IF(P11=1,G11/5*D11,"") | P11: =IF(COUNT(E11:F11)<>2,0,IF(AND(MIN(E11:F11)>=0,MAX(E11:F11)<=5),1,0)) -> 0 | Q11: =IF(AND(I11="確認済み",J11<>"",K11<>"",L11<>""),1,0) -> 0 | R11: =IF(AND(P11=1,ISNUMBER(O11),O11>=0,O11<=5),(O11-G11)/5*D11,"")
A12: B2 | B12: シーンとジオメトリ | C12: 構造と接合部 | D12: {=INDEX('60項目の基準'!$D$6:$D$65,MATCH(A12,'60項目の基準'!$A$6:$A$65,0))} -> 2.4 | G12: =IF(P12=1,ROUND(E12*'使用方法'!$B$5+F12*'使用方法'!$B$6,6),"") | H12: =IF(P12=1,G12/5*D12,"") | P12: =IF(COUNT(E12:F12)<>2,0,IF(AND(MIN(E12:F12)>=0,MAX(E12:F12)<=5),1,0)) -> 0 | Q12: =IF(AND(I12="確認済み",J12<>"",K12<>"",L12<>""),1,0) -> 0 | R12: =IF(AND(P12=1,ISNUMBER(O12),O12>=0,O12<=5),(O12-G12)/5*D12,"")
A13: B3 | B13: シーンとジオメトリ | C13: ディテール密度と反復感の抑制 | D13: {=INDEX('60項目の基準'!$D$6:$D$65,MATCH(A13,'60項目の基準'!$A$6:$A$65,0))} -> 2.4 | G13: =IF(P13=1,ROUND(E13*'使用方法'!$B$5+F13*'使用方法'!$B$6,6),"") | H13: =IF(P13=1,G13/5*D13,"") | P13: =IF(COUNT(E13:F13)<>2,0,IF(AND(MIN(E13:F13)>=0,MAX(E13:F13)<=5),1,0)) -> 0 | Q13: =IF(AND(I13="確認済み",J13<>"",K13<>"",L13<>""),1,0) -> 0 | R13: =IF(AND(P13=1,ISNUMBER(O13),O13>=0,O13<=5),(O13-G13)/5*D13,"")
A14: B4 | B14: シーンとジオメトリ | C14: シーンへのなじみと環境ストーリーテリング | D14: {=INDEX('60項目の基準'!$D$6:$D$65,MATCH(A14,'60項目の基準'!$A$6:$A$65,0))} -> 2.4 | G14: =IF(P14=1,ROUND(E14*'使用方法'!$B$5+F14*'使用方法'!$B$6,6),"") | H14: =IF(P14=1,G14/5*D14,"") | P14: =IF(COUNT(E14:F14)<>2,0,IF(AND(MIN(E14:F14)>=0,MAX(E14:F14)<=5),1,0)) -> 0 | Q14: =IF(AND(I14="確認済み",J14<>"",K14<>"",L14<>""),1,0) -> 0 | R14: =IF(AND(P14=1,ISNUMBER(O14),O14>=0,O14<=5),(O14-G14)/5*D14,"")
A15: B5 | B15: シーンとジオメトリ | C15: 描画距離とストリーミングの完全性 | D15: {=INDEX('60項目の基準'!$D$6:$D$65,MATCH(A15,'60項目の基準'!$A$6:$A$65,0))} -> 2.4 | G15: =IF(P15=1,ROUND(E15*'使用方法'!$B$5+F15*'使用方法'!$B$6,6),"") | H15: =IF(P15=1,G15/5*D15,"") | P15: =IF(COUNT(E15:F15)<>2,0,IF(AND(MIN(E15:F15)>=0,MAX(E15:F15)<=5),1,0)) -> 0 | Q15: =IF(AND(I15="確認済み",J15<>"",K15<>"",L15<>""),1,0) -> 0 | R15: =IF(AND(P15=1,ISNUMBER(O15),O15>=0,O15<=5),(O15-G15)/5*D15,"")
A16: C1 | B16: マテリアルとテクスチャ | C16: PBRの反応と素材の描き分け | D16: {=INDEX('60項目の基準'!$D$6:$D$65,MATCH(A16,'60項目の基準'!$A$6:$A$65,0))} -> 2 | G16: =IF(P16=1,ROUND(E16*'使用方法'!$B$5+F16*'使用方法'!$B$6,6),"") | H16: =IF(P16=1,G16/5*D16,"") | P16: =IF(COUNT(E16:F16)<>2,0,IF(AND(MIN(E16:F16)>=0,MAX(E16:F16)<=5),1,0)) -> 0 | Q16: =IF(AND(I16="確認済み",J16<>"",K16<>"",L16<>""),1,0) -> 0 | R16: =IF(AND(P16=1,ISNUMBER(O16),O16>=0,O16<=5),(O16-G16)/5*D16,"")
A17: C2 | B17: マテリアルとテクスチャ | C17: テクスチャの実効的な鮮明さ | D17: {=INDEX('60項目の基準'!$D$6:$D$65,MATCH(A17,'60項目の基準'!$A$6:$A$65,0))} -> 2 | G17: =IF(P17=1,ROUND(E17*'使用方法'!$B$5+F17*'使用方法'!$B$6,6),"") | H17: =IF(P17=1,G17/5*D17,"") | P17: =IF(COUNT(E17:F17)<>2,0,IF(AND(MIN(E17:F17)>=0,MAX(E17:F17)<=5),1,0)) -> 0 | Q17: =IF(AND(I17="確認済み",J17<>"",K17<>"",L17<>""),1,0) -> 0 | R17: =IF(AND(P17=1,ISNUMBER(O17),O17>=0,O17<=5),(O17-G17)/5*D17,"")
... A65: L5 | B65: ゲーム全編の一貫性 | C65: モード・バージョン間の一貫性 | D65: {=INDEX('60項目の基準'!$D$6:$D$65,MATCH(A65,'60項目の基準'!$A$6:$A$65,0))} -> 1 | G65: =IF(P65=1,ROUND(E65*'使用方法'!$B$5+F65*'使用方法'!$B$6,6),"") | H65: =IF(P65=1,G65/5*D65,"") | P65: =IF(COUNT(E65:F65)<>2,0,IF(AND(MIN(E65:F65)>=0,MAX(E65:F65)<=5),1,0)) -> 0 | Q65: =IF(AND(I65="確認済み",J65<>"",K65<>"",L65<>""),1,0) -> 0 | R65: =IF(AND(P65=1,ISNUMBER(O65),O65>=0,O65<=5),(O65-G65)/5*D65,"")

Sheet 60項目の基準
A2: リアル系アクションゲームのアート基準（60項目）
A4: 3点は基本合格、4点は高品質な製品の基準とする。5点には高負荷シーンでも同等の完成度を維持することが求められる。技術方式やパラメータそのものは直接の加点対象としない。
A5: 番号 | B5: 評価カテゴリ | C5: 評価項目 | D5: 満点時の加重点 | E5: 3点：基本合格 | F5: 4点：高品質 | G5: 5点：最高水準の表現 | H5: 提出すべき根拠資料 | I5: 優先的な改善方針 | J5: 参考資料
A6: A1 | B6: ビジュアルデザイン全般 | C6: ビジュアル表現の統一 | D6: 1.2 | E6: 同一レベル内で色彩、プロポーション、工業デザインに明らかな不整合がない | F6: レベル間で一貫性を保ち、主要エリアごとの違いが明確に表現されている | G6: 作品全体に強い個性があり、細部まで一貫してテーマを支えている | H6: アートスタイルガイド、各チャプターの固定カメラによる画像一覧 | I6: 「ビジュアル表現の統一」について、通常シーンと高負荷シーンの不具合を記録し、プレイや映像の説得力に影響する問題を優先して修正する。 | J6: プロジェクト内の推奨基準。技術的な仕組みの根拠は付属レポートを参照
A7: A2 | B7: ビジュアルデザイン全般 | C7: 構図と視覚的な優先順位 | D7: 1.2 | E7: 通常のカメラ視点で、主要な被写体と背景を見分けられる | F7: 移動中、ロックオン中、多数の敵が入り乱れる戦闘中も、視覚的な優先順位が保たれる | G7: 複雑なシーンでも自然に視線を誘導でき、見栄えも優れている | H7: 通常シーン／高負荷シーンの戦闘動画、ターゲットの識別テスト | I7: 「構図と視覚的な優先順位」について、通常シーンと高負荷シーンの不具合を記録し、プレイや映像の説得力に影響する問題を優先して修正する。 | J7: プロジェクト内の推奨基準。技術的な仕組みの根拠は付属レポートを参照
A8: A3 | B8: ビジュアルデザイン全般 | C8: 空間とランドマーク | D8: 1.2 | E8: 進行ルート、ランドマーク、戦闘空間を識別できる | F8: 似たシーンでも、構図や光・色の違いによって印象に残る特徴を作れている | G8: 空間を通じた物語表現とゲームプレイが結びつき、連続性と独自性のある視覚体験を生み出している | H8: レベル内のルート、迷った箇所や誤認の記録 | I8: 「空間とランドマーク」について、通常シーンと高負荷シーンの不具合を記録し、プレイや映像の説得力に影響する問題を優先して修正する。 | J8: プロジェクト内の推奨基準。技術的な仕組みの根拠は付属レポートを参照
A9: A4 | B9: ビジュアルデザイン全般 | C9: 色彩と明暗の設計 | D9: 1.2 | E9: 意図しない黒つぶれ、白飛び、階調の乏しい灰色の画面が広い範囲に発生しない | F9: 光と色の変化がプレイのテンポを支え、敵のシルエットを安定して識別できる | G9: 抑制の利いた豊かな明暗の階調がゲーム全編で保たれている | H9: 各シーンの明るさ・色彩を確認できるスクリーンショット、露出設定 | I9: 「色彩と明暗の設計」について、通常シーンと高負荷シーンの不具合を記録し、プレイや映像の説得力に影響する問題を優先して修正する。 | J9: プロジェクト内の推奨基準。技術的な仕組みの根拠は付属レポートを参照
A10: A5 | B10: ビジュアルデザイン全般 | C10: リメイクにおける現代的な表現 | D10: 1.2 | E10: IPらしさを維持し、時代感に明らかな不整合がない | F10: 原作の代表的なシーンが、プロポーション、ライティング、マテリアルの各面で統一感をもって再構築されている | G10: 現代的なディテールと原作の雰囲気が融合し、リメイク独自の象徴的なカットがある | H10: 原作の対応するカット、リメイクにおけるアートの意図を説明した資料 | I10: 「リメイクにおける現代的な表現」について、通常シーンと高負荷シーンの不具合を記録し、プレイや映像の説得力に影響する問題を優先して修正する。 | J10: プロジェクト内の推奨基準。技術的な仕組みの根拠は付属レポートを参照
A11: B1 | B11: シーンとジオメトリ | C11: スケールとシルエット | D11: 2.4 | E11: ドア、段差、構造物、人物の大きさの比率に説得力がある | F11: 通常の視距離で、曲面、ベベル、主要なシルエットが適切に表現されている | G11: 近景・中景・遠景のいずれもシルエットが精緻で、構図に寄与している | H11: ゲームカメラによる近景・中景・遠景、ジオメトリ／LODの説明 | I11: 「スケールとシルエット」について、通常シーンと高負荷シーンの不具合を記録し、プレイや映像の説得力に影響する問題を優先して修正する。 | J11: プロジェクト内の推奨基準。技術的な仕組みの根拠は付属レポートを参照
A12: B2 | B12: シーンとジオメトリ | C12: 構造と接合部 | D12: 2.4 | E12: 壁と床の境界、設備の支持部、建築物の接合部に構造上の不自然さがない | F12: 遮蔽物の裏側や脇道にも、組み合わせたパーツの明らかな綻びがない | G12: 構造の階層、荷重のかかり方、機能面のディテールに高い説得力がある | H12: 通常ルートと極端なカメラ位置からの映像、問題箇所の座標 | I12: 「構造と接合部」について、通常シーンと高負荷シーンの不具合を記録し、プレイや映像の説得力に影響する問題を優先して修正する。 | J12: プロジェクト内の推奨基準。技術的な仕組みの根拠は付属レポートを参照
A13: B3 | B13: シーンとジオメトリ | C13: ディテール密度と反復感の抑制 | D13: 2.4 | E13: 通常ルートで、明らかにスカスカな箇所や単調な繰り返し配置が目立たない | F13: 大・中・小のディテールに階層があり、テクスチャやモジュールの反復感が効果的に抑えられている | G13: 物語や戦闘のテンポに応じて密度が変化し、場面ごとの違いが一貫して保たれている | H13: チャプターごとのサンプル、繰り返し使用するモジュールの配置、画面内の占有率 | I13: 「ディテール密度と反復感の抑制」について、通常シーンと高負荷シーンの不具合を記録し、プレイや映像の説得力に影響する問題を優先して修正する。 | J13: プロジェクト内の推奨基準。技術的な仕組みの根拠は付属レポートを参照
A14: B4 | B14: シーンとジオメトリ | C14: シーンへのなじみと環境ストーリーテリング | D14: 2.4 | E14: 植生、破片、損傷、汚れが環境に合っている | F14: 地面との接続が自然で、使用痕や破壊痕の付き方に合理性がある | G14: 探索で発見できるディテールが豊富でありながら、視覚的なノイズになっていない | H14: 地面とのなじませ方、デカール、摩耗、環境ストーリーテリングの作例 | I14: 「シーンへのなじみと環境ストーリーテリング」について、通常シーンと高負荷シーンの不具合を記録し、プレイや映像の説得力に影響する問題を優先して修正する。 | J14: プロジェクト内の推奨基準。技術的な仕組みの根拠は付属レポートを参照
A15: B5 | B15: シーンとジオメトリ | C15: 描画距離とストリーミングの完全性 | D15: 2.4 | E15: 通常の移動ルートで、目立つ欠落やオブジェクトの突然の出現がない | F15: 高速移動中の振り返りやシーン切り替えでも、ジオメトリのディテールが連続している | G15: 高負荷となる移動や遠距離表示でも、目を引くような切り替わりがない | H15: Nanite／LOD／HLODとカリングの設定；コールド／ウォーム状態での走行録画 | I15: 「描画距離とストリーミングの完全性」について、通常シーンと高負荷シーンの不具合を記録し、プレイや映像の説得力に影響する問題を優先して修正する。 | J15: プロジェクト内の推奨基準。技術的な仕組みの根拠は付属レポートを参照
A16: C1 | B16: マテリアルとテクスチャ | C16: PBRの反応と素材の描き分け | D16: 2 | E16: 金属、塗装、プラスチック、石材の光への反応を区別できる | F16: 異なるライティングでも質感に説得力があり、全体がプラスチックのように見えない | G16: 複雑な複合マテリアルでも、光のエネルギーと質感の層が繊細かつ安定して表現される | H16: BaseColor／Roughness／Metallic表示；マテリアルサンプル | I16: 「PBRの反応と素材の描き分け」について、通常シーンと高負荷シーンの不具合を記録し、プレイや映像の説得力に影響する問題を優先して修正する。 | J16: プロジェクト内の推奨基準。技術的な仕組みの根拠は付属レポートを参照
A17: C2 | B17: マテリアルとテクスチャ | C17: テクスチャの実効的な鮮明さ | D17: 2 | E17: 通常のプレイ距離で主要な対象がぼやけず、テクスチャ密度に不自然な差がない | F17: 近景や浅い角度からの観察でもディテールが十分で、過度なシャープネスがない | G17: 主な観察距離でディテールが豊富にあり、移動中も継続して識別できる | H17: ソース／インポート／常駐ミップ；テクセル密度；異方性フィルタリング設定 | I17: 「テクスチャの実効的な鮮明さ」について、通常シーンと高負荷シーンの不具合を記録し、プレイや映像の説得力に影響する問題を優先して修正する。 | J17: プロジェクト内の推奨基準。技術的な仕組みの根拠は付属レポートを参照
... A65: L5 | B65: ゲーム全編の一貫性 | C65: モード・バージョン間の一貫性 | D65: 1 | E65: レビューに提出したバージョンとモードを再現できる | F65: プロモーションの主要ショットと提供を約束したモードとの差が明示され、説明できる | G65: 通常プレイでも、プロモーションで示した主要なビジュアル特性を継続して実現できる | H65: バージョン番号；プラットフォーム別モード一覧；プロモーション映像と実機映像の対応比較 | I65: 「モード・バージョン間の一貫性」について通常シーンと高負荷シーンの不具合を記録し、プレイや画面の説得力に影響する問題を優先して修正する。 | J65: プロジェクト内の推奨基準。技術的な仕組みの根拠は付属レポートを参照

Sheet 追加データ一覧
A2: 追加データ一覧
A4: まず同一ビルドのPS5実機映像とパフォーマンス記録を入手し、その後にオン／オフ比較とパラメータの確認を行う。担当者が事実関係を確認してから、評価者が採点入力シートで採点する。
A5: 番号 | B5: 評価カテゴリ | C5: 評価項目 | D5: 提出が必要なデータ／根拠資料 | E5: 把握している事実 | F5: 確認が必要な事項 | G5: 担当者 | H5: 最新の測定結果 | I5: 根拠資料へのリンク | J5: ビルド／測定日 | K5: 収集状況
A6: A1 | B6: ビジュアルデザイン全般 | C6: ビジュアル表現の統一 | D6: アートスタイルガイド、各チャプターの固定カメラによる画像一覧
A7: A2 | B7: ビジュアルデザイン全般 | C7: 構図と視覚的な優先順位 | D7: 通常シーン／高負荷シーンの戦闘動画、ターゲットの識別テスト
A8: A3 | B8: ビジュアルデザイン全般 | C8: 空間とランドマーク | D8: レベル内のルート、迷った箇所や誤認の記録
A9: A4 | B9: ビジュアルデザイン全般 | C9: 色彩と明暗の設計 | D9: 各シーンの明るさ・色彩を確認できるスクリーンショット、露出設定
A10: A5 | B10: ビジュアルデザイン全般 | C10: リメイクにおける現代的な表現 | D10: 原作の対応するカット、リメイクにおけるアートの意図を説明した資料
A11: B1 | B11: シーンとジオメトリ | C11: スケールとシルエット | D11: ゲームカメラによる近景・中景・遠景、ジオメトリ／LODの説明
A12: B2 | B12: シーンとジオメトリ | C12: 構造と接合部 | D12: 通常ルートと極端なカメラ位置からの映像、問題箇所の座標
A13: B3 | B13: シーンとジオメトリ | C13: ディテール密度と反復感の抑制 | D13: チャプターごとのサンプル、繰り返し使用するモジュールの配置、画面内の占有率
A14: B4 | B14: シーンとジオメトリ | C14: シーンへのなじみと環境ストーリーテリング | D14: 地面とのなじませ方、デカール、摩耗、環境ストーリーテリングの作例
A15: B5 | B15: シーンとジオメトリ | C15: 描画距離とストリーミングの完全性 | D15: Nanite／LOD／HLODとカリングの設定；コールド／ウォーム状態での走行録画
A16: C1 | B16: マテリアルとテクスチャ | C16: PBRの反応と素材の描き分け | D16: BaseColor／Roughness／Metallic表示；マテリアルサンプル
A17: C2 | B17: マテリアルとテクスチャ | C17: テクスチャの実効的な鮮明さ | D17: ソース／インポート／常駐ミップ；テクセル密度；異方性フィルタリング設定
... A24: D4 | B24: ライティングと間接光 | C24: 動的な光への反応 | D24: 動的光源／破壊の録画；更新遅延；GPU処理時間の内訳
A25: D5 | B25: ライティングと間接光 | C25: ゲーム全編のライティング品質 | D25: 各章のコンタクトシート；ライティング品質設定と例外一覧 | E25: ユーザーからの報告：60FPSを目指して比較的低い設定を採用している。実際のPS5設定は要追加 | F25: 選択モードのPS5デバイス設定、品質レベル、プロジェクト設定と実行時CVarのオーバーライド、スクリーンパーセンテージ、GPU／CPUの項目別処理時間を提出する。 | K25: 要追加
A26: E1 | B26: シャドウと接触表現 | C26: キャラクターと物体の接地感 | D26: 足元／壁の隅／斜面の録画；コンタクトシャドウの方式
A27: E2 | B27: シャドウと接触表現 | C27: シャドウの形状と柔らかさ | D27: 主光源とローカルライトのシャドウ例；シャドウ方式
A28: E3 | B28: シャドウと接触表現 | C28: 細部の遮蔽 | D28: 実際に使用する遮蔽方式の説明；その方式に対応したA/B比較 | E28: ユーザーからの報告：先方はAOが有効と説明しているが、現在のAOデバッグビューは全面が白い。具体的な実装経路は未確認 | F28: エンジンのバージョン、レンダリングパス、GIと遮蔽の方式、および各方式に対応する診断結果と、足元／壁の隅を同一カメラ位置で撮影したオン／オフ比較を提出する。 | K28: 要追加
A29: E4 | B29: シャドウと接触表現 | C29: シャドウの適用範囲と光漏れ | D29: シャドウ距離／解像度；薄い壁と遠景の録画
A30: E5 | B30: シャドウと接触表現 | C30: 動的シャドウの安定性 | D30: VSM／従来型シャドウの診断；動的なキャッシュ無効化と処理時間
A31: F1 | B31: 反射と環境ライティングの入力データ | C31: 主要マテリアルの反射 | D31: 代表的なマテリアルのLit表示録画；反射方式と品質設定
A32: F2 | B32: 反射と環境ライティングの入力データ | C32: 画面外・遮蔽時の挙動 | D32: SSR／Lumen／反射キャプチャの併用方式；対象が画面外に出る際の録画
A33: F3 | B33: 反射と環境ライティングの入力データ | C33: 粗い表面の反射とノイズ | D33: ラフネスの段階別テスト；デノイズ／トレースのパラメータ
A34: F4 | B34: 反射と環境ライティングの入力データ | C34: 空とHDRIの整合性 | D34: HDRIの用途／形式／ダイナミックレンジ；SkyLightのソースタイプ
A35: F5 | B35: 反射と環境ライティングの入力データ | C35: 解像度とキャプチャの有効性 | D35: ソース／実行時のサイズ；キューブマップ解像度；条件を統制した4K／8KのA/B比較 | E35: ユーザーからの報告：HDRIのソース画像は4K。実行時の解像度、用途、サンプリングは未確認 | F35: ソース画像の用途は何か。ソース形式／ダイナミックレンジ、インポート設定と常駐mip、SkyLight／リフレクションキャプチャの解像度、および同一カメラ位置での4K／8K比較を提出する。 | K35: 要追加
A36: G1 | B36: 大気表現とフォグ | C36: 近景・中景・遠景の奥行き | D36: 同一カメラ位置からの遠距離表示；天候とハイトフォグのパラメータ
A37: G2 | B37: 大気表現とフォグ | C37: 局所的な分布と高さの関係 | D37: 局所的な霧の内容；密度／消散係数；オン／オフ比較
A38: G3 | B38: 大気表現とフォグ | C38: 光の散乱と遮蔽 | D38: 逆光のショット；ライトのボリューメトリックへの寄与とシャドウ
A39: G4 | B39: 大気表現とフォグ | C39: 動きのある場面のフォグ品質 | D39: グリッド／距離；刀を振った際の閃光と方向転換の録画；GPU処理時間 | E39: ユーザーからの報告：ボリュメトリックフォグは有効だが、確認したショットでは変化が明確に見られない | F39: 同一カメラ位置でのオン／オフ比較と、カメラの高速回転／動的ライティングを収録した映像を提出する。密度、消散、グリッド／距離、ライトのボリュメトリック寄与、GPUコストを記録する。 | K39: 要追加
A40: G5 | B40: 大気表現とフォグ | C40: 雰囲気と視認性のバランス | D40: 戦闘の視認性を確認する録画；霧のオン／オフとシルエットの比較
A41: H1 | B41: キャラクターとアニメーション表現 | C41: 主人公と主要な敵の外観 | D41: 実機の近景・中景；キャラクターのマテリアル／LOD／皮膚または装甲
A42: H2 | B42: キャラクターとアニメーション表現 | C42: キャラクターのシーンへのなじみ | D42: 異なるライティングのエリアを通過する録画
A43: H3 | B43: キャラクターとアニメーション表現 | C43: 変形とアニメーションのつながり | D43: アニメーション集；スケルトン／クロス／付属パーツの設定
A44: H4 | B44: キャラクターとアニメーション表現 | C44: 武器と切断・破壊表現 | D44: 切断／破断の録画；破片数の上限と消去ルール
A45: H5 | B45: キャラクターとアニメーション表現 | C45: 動きのある場面のキャラクターディテールの安定性 | D45: 髪／布／装着物の近景および高負荷シーンの録画
A46: I1 | B46: エフェクトと戦闘フィードバック | C46: 攻撃予兆とターゲットの視認性 | D46: 最大負荷となる戦闘の録画；設計で定めた予兆の提示時間
A47: I2 | B47: エフェクトと戦闘フィードバック | C47: ヒットのタイミングと重み | D47: フレーム単位のヒット時系列；異なる表面へのヒット例
A48: I3 | B48: エフェクトと戦闘フィードバック | C48: エフェクトの質感と立体感 | D48: Niagara／マテリアル設定；深度の境界と斜めからの視点の録画
...

Sheet 使用方法
A2: 使用方法と採点基準
A5: 通常シーンの重み | B5: 0.7 | C5: 主要なレベル、ライティング、マテリアルを網羅するようにシーンを選ぶ。
A6: 高負荷シーンの重み | B6: 0.3 | C6: カメラの高速回転、最大負荷の戦闘、破壊、パーティクル、シーン切り替え。
A8: スコア | B8: 共通の定義 | C8: 判定要件
A9: 0 | B9: 重大な破綻 | C9: 対象項目が実際に機能せず、製品体験を大きく損なっている。データ不足を0で表してはならない。
A10: 1 | B10: 明らかに水準を下回る | C10: 通常プレイで問題に気づき、説得力、視認性、完成度を損なっている。
A11: 2 | B11: 基本合格水準に未達 | C11: 機能は画面に表れているが、よく見るショットで不具合が目立ち、重点的な修正が必要。
A12: 3 | B12: 基本合格 | C12: 通常シーンのプレイで、基本的な説得力がある。一般的な不具合は管理可能で、当該項目の基本基準を満たしている。
A13: 4 | B13: 高品質 | C13: 大半のプレイシーンで、安定して高品質を達成している。不具合は軽微で、表現に一貫性がある。
A14: 5 | B14: 最高水準の表現 | C14: 高い完成度と動的な安定性を兼ね備え、高負荷シーンでの検証にも耐えられる。
A16: スコアの計算 | B16: 計算式 | C16: データ不足時の扱い
A17: 項目別の統合スコア | B17: 通常シーン × 70% + 高負荷シーン × 30% | C17: 両方のスコアが有効な場合のみ計算する。採点は0～5の範囲で、小数も使用できる。
A18: 項目別の加重点 | B18: 統合スコア ÷ 5 × 満点時の加重点 | C18: 60項目の満点時の加重点は合計100。各評価カテゴリの配点比率に応じて配分する。
A19: 根拠資料の重み付きカバー率 | B19: 確認済み項目の重みの合計 ÷ 100 | C19: 両シーンが確認済みで、根拠資料とビルド／カメラ位置の情報がそろっていること。採点のカバー率も指標の重みで集計し、完備した項目数は別に示す。
A20: 正式な総合スコアとランク | B20: 60項目の採点と根拠資料がそろってから判定する | C20: 不足がある場合は空欄のままとする。測定済みの少数項目から、製品全体のランクを推定してはならない。
A22: 下限スコア | B22: ランク | C22: 製品レビューでの意味
A23: 0 | B23: D 基本ライン未達 | C23: 0～59.9：ビジュアルの基礎に明らかな不足がある。
A24: 60 | B24: C 基本部分が完成 | C24: 60～69.9：基本部分は完成しているが、製品としての競争力は限定的。
A25: 70 | B25: B 目標との明確な差が残る | C25: 70～79.9：高品質の目標に対して、依然として大きな弱点がある。
A26: 80 | B26: A 高品質の目標水準 | C26: 80～89.9：主要な評価カテゴリ、選択モードのパフォーマンス、不具合審査も合格する必要がある。
A27: 90 | B27: S トップ水準のスコア帯 | C27: 90～100：すべての評価カテゴリが4以上で、重大な不具合がない場合に限り、トップ水準と認定することを推奨する。
A30: 固定する評価条件 | B30: プラットフォーム／モード／ビルド | C30: ベースモデルのPS5を使用する。30／40／60 FPSの各モードに、それぞれ別の採点表を使用する。60FPSを優先目標とするが、60FPSでないことだけを理由に不合格にはしない。
A31: 根拠資料の内容 | B31: 最終的な実機表示を先に確認し、その後に技術的説明を確認する | C31: 可逆圧縮または無圧縮のスクリーンショット、通常プレイの録画、同一カメラ位置でのA/B比較、GPUとCPUのフレーム時間、不具合の発生頻度を残す。
A32: 解像度とサンプリング | B32: テクスチャの公称サイズだけで判断しない | C32: HDRIは用途、ダイナミックレンジ、有効なmip、サンプリング、実際の反射表現を確認する。4Kか8Kかという点だけでは加点も減点もしない。
A33: AOとフォグ | B33: 有効化スイッチだけで判断しない | C33: レンダリングパスと最終画面の空間的な奥行きを確認する。白いAOビューだけでは、画面全体に遮蔽がないとは断定できない。晴天でフォグが薄いことを理由に自動的に減点しない。
A34: ベンチマーク比較の方法 | B34: 同一プラットフォーム、同一モード、同種のシーン | C34: カメラ位置、環境の複雑さ、動きの状態を合わせる。K5は提供を約束したSDR／HDRの対応範囲に基づいて評価し、HDR非対応という理由だけで低評価にしない。
A35: 適用対象外の項目 | B35: 評価前に対象範囲と重みを固定する | C35: 本表では、原則として60項目すべてを適用する。実際に適用対象外となる項目がある場合は、ディレクターの署名を得て基準と重みを調整してから採点を始める。0を入力したり、弱点に当たる項目をその場で削除したりしてはならない。
A36: 基準の位置づけ | B36: プロジェクト評価の推奨基準 v1.0 | C36: ランクと重みは、本プロジェクトの評価基準案である。初回の実機比較を通じて基準を調整し、一般的な業界認証と称してはならない。
A38: 高品質としての最低受入基準 | B38: ビジュアルスコア ≥ 80 | C38: D：ライティング、J：動きのある画面の品質が4以上。B：シーン、C：マテリアル、E：シャドウ、H：キャラクターが3.5以上。
A39: 高負荷シーンと各項目の最低基準 | B39: I1の高負荷シーンスコア ≥ 4 | C39: すべての項目の統合スコアを3以上とし、高得点で明らかな弱点が隠れないようにする。
A40: 製品の受入判定 | B40: ビジュアルとパフォーマンスを分ける | C40: ビジュアルの最低基準を満たしたうえで、選択モードのパフォーマンスとアクションの応答性、重大な不具合の審査がすべて合格した場合にのみ、受入合格と表示する。
A41: 90点でのトップ水準認定 | B41: スコア帯と認定を分ける | C41: 90点は数値上の区分にすぎない。全12評価カテゴリが4以上で、重大な不具合がなく、選択モードのパフォーマンスが合格した場合にのみ、トップ水準と認定することを推奨する。
A42: 低フレームレートモードの審査 | B42: アクションの応答性は必ず実測する | C42: 40 FPSでは、表示リフレッシュレートの条件も確認する。30 FPSでは、アクションの応答性と動きのある画面の鮮明さも確認し、静止画の品質だけで評価しない。
