Workbook

Sheet 对标总览
A2: 写实游戏画面品质对标
A4: 资料截至 2026-10-12｜0–5单项参考区间；按旧版评测推断，非媒体原分。
A5: 维度 | B5: 权重 | C5: 本项目 | D5: 建议目标 | E5: 合金装备Delta | F5: 黑神话：悟空 | G5: 地狱之刃2 | H5: 寂静岭2重制 | I5: 恶魔之魂重制 | J5: 影之刃零
E6: PC Ultra 2025首发样本 | F6: PC高端 D/E/F：Full RT 2024-08 | G6: Xbox Series X 原版30fps 2024-05 | H6: 基础PS5 品质30fps 2024-10 | I6: 基础PS5 品质30fps 2020历史例外 | J6: 未发售 计划2026-10-29 全部待评
A7: A 整体视觉设计 | B7: 6 | C7: =IF('项目对照'!L9="有效",'项目对照'!D9,"") | D7: =IF(ISNUMBER('项目对照'!I9),'项目对照'!I9,"") -> 4 | E7: =IF('评分依据'!K6=0,"待评",TEXT('评分依据'!F6,"0.0")&"–"&TEXT('评分依据'!G6,"0.0")) -> 4.0–4.5 | F7: =IF('评分依据'!K18=0,"待评",TEXT('评分依据'!F18,"0.0")&"–"&TEXT('评分依据'!G18,"0.0")) -> 4.0–4.5 | G7: =IF('评分依据'!K30=0,"待评",TEXT('评分依据'!F30,"0.0")&"–"&TEXT('评分依据'!G30,"0.0")) -> 4.5–5.0 | H7: =IF('评分依据'!K42=0,"待评",TEXT('评分依据'!F42,"0.0")&"–"&TEXT('评分依据'!G42,"0.0")) -> 4.0–4.5 | I7: =IF('评分依据'!K54=0,"待评",TEXT('评分依据'!F54,"0.0")&"–"&TEXT('评分依据'!G54,"0.0")) -> 4.0–4.5 | J7: =IF('评分依据'!K66=0,"待评",TEXT('评分依据'!F66,"0.0")&"–"&TEXT('评分依据'!G66,"0.0")) -> 待评
A8: B 场景与几何 | B8: 12 | C8: =IF('项目对照'!L10="有效",'项目对照'!D10,"") | D8: =IF(ISNUMBER('项目对照'!I10),'项目对照'!I10,"") -> 4.5 | E8: =IF('评分依据'!K7=0,"待评",TEXT('评分依据'!F7,"0.0")&"–"&TEXT('评分依据'!G7,"0.0")) -> 4.0–4.5 | F8: =IF('评分依据'!K19=0,"待评",TEXT('评分依据'!F19,"0.0")&"–"&TEXT('评分依据'!G19,"0.0")) -> 4.0–4.5 | G8: =IF('评分依据'!K31=0,"待评",TEXT('评分依据'!F31,"0.0")&"–"&TEXT('评分依据'!G31,"0.0")) -> 4.5–5.0 | H8: =IF('评分依据'!K43=0,"待评",TEXT('评分依据'!F43,"0.0")&"–"&TEXT('评分依据'!G43,"0.0")) -> 4.0–4.5 | I8: =IF('评分依据'!K55=0,"待评",TEXT('评分依据'!F55,"0.0")&"–"&TEXT('评分依据'!G55,"0.0")) -> 4.0–4.5 | J8: =IF('评分依据'!K67=0,"待评",TEXT('评分依据'!F67,"0.0")&"–"&TEXT('评分依据'!G67,"0.0")) -> 待评
A9: C 材质与纹理 | B9: 10 | C9: =IF('项目对照'!L11="有效",'项目对照'!D11,"") | D9: =IF(ISNUMBER('项目对照'!I11),'项目对照'!I11,"") -> 4.5 | E9: =IF('评分依据'!K8=0,"待评",TEXT('评分依据'!F8,"0.0")&"–"&TEXT('评分依据'!G8,"0.0")) -> 4.0–4.5 | F9: =IF('评分依据'!K20=0,"待评",TEXT('评分依据'!F20,"0.0")&"–"&TEXT('评分依据'!G20,"0.0")) -> 3.5–4.5 | G9: =IF('评分依据'!K32=0,"待评",TEXT('评分依据'!F32,"0.0")&"–"&TEXT('评分依据'!G32,"0.0")) -> 4.5–5.0 | H9: =IF('评分依据'!K44=0,"待评",TEXT('评分依据'!F44,"0.0")&"–"&TEXT('评分依据'!G44,"0.0")) -> 3.5–4.5 | I9: =IF('评分依据'!K56=0,"待评",TEXT('评分依据'!F56,"0.0")&"–"&TEXT('评分依据'!G56,"0.0")) -> 4.0–4.5 | J9: =IF('评分依据'!K68=0,"待评",TEXT('评分依据'!F68,"0.0")&"–"&TEXT('评分依据'!G68,"0.0")) -> 待评
A10: D 灯光与间接光 | B10: 14 | C10: =IF('项目对照'!L12="有效",'项目对照'!D12,"") | D10: =IF(ISNUMBER('项目对照'!I12),'项目对照'!I12,"") -> 4.5 | E10: =IF('评分依据'!K9=0,"待评",TEXT('评分依据'!F9,"0.0")&"–"&TEXT('评分依据'!G9,"0.0")) -> 4.0–4.5 | F10: =IF('评分依据'!K21=0,"待评",TEXT('评分依据'!F21,"0.0")&"–"&TEXT('评分依据'!G21,"0.0")) -> 4.0–4.5 | G10: =IF('评分依据'!K33=0,"待评",TEXT('评分依据'!F33,"0.0")&"–"&TEXT('评分依据'!G33,"0.0")) -> 4.5–5.0 | H10: =IF('评分依据'!K45=0,"待评",TEXT('评分依据'!F45,"0.0")&"–"&TEXT('评分依据'!G45,"0.0")) -> 4.0–4.5 | I10: =IF('评分依据'!K57=0,"待评",TEXT('评分依据'!F57,"0.0")&"–"&TEXT('评分依据'!G57,"0.0")) -> 4.0–4.5 | J10: =IF('评分依据'!K69=0,"待评",TEXT('评分依据'!F69,"0.0")&"–"&TEXT('评分依据'!G69,"0.0")) -> 待评
A11: E 阴影与接触关系 | B11: 8 | C11: =IF('项目对照'!L13="有效",'项目对照'!D13,"") | D11: =IF(ISNUMBER('项目对照'!I13),'项目对照'!I13,"") -> 4 | E11: =IF('评分依据'!K10=0,"待评",TEXT('评分依据'!F10,"0.0")&"–"&TEXT('评分依据'!G10,"0.0")) -> 待评 | F11: =IF('评分依据'!K22=0,"待评",TEXT('评分依据'!F22,"0.0")&"–"&TEXT('评分依据'!G22,"0.0")) -> 4.0–4.5 | G11: =IF('评分依据'!K34=0,"待评",TEXT('评分依据'!F34,"0.0")&"–"&TEXT('评分依据'!G34,"0.0")) -> 4.5–5.0 | H11: =IF('评分依据'!K46=0,"待评",TEXT('评分依据'!F46,"0.0")&"–"&TEXT('评分依据'!G46,"0.0")) -> 待评 | I11: =IF('评分依据'!K58=0,"待评",TEXT('评分依据'!F58,"0.0")&"–"&TEXT('评分依据'!G58,"0.0")) -> 4.0–4.5 | J11: =IF('评分依据'!K70=0,"待评",TEXT('评分依据'!F70,"0.0")&"–"&TEXT('评分依据'!G70,"0.0")) -> 待评
A12: F 反射与环境照明输入 | B12: 6 | C12: =IF('项目对照'!L14="有效",'项目对照'!D14,"") | D12: =IF(ISNUMBER('项目对照'!I14),'项目对照'!I14,"") -> 4 | E12: =IF('评分依据'!K11=0,"待评",TEXT('评分依据'!F11,"0.0")&"–"&TEXT('评分依据'!G11,"0.0")) -> 待评 | F12: =IF('评分依据'!K23=0,"待评",TEXT('评分依据'!F23,"0.0")&"–"&TEXT('评分依据'!G23,"0.0")) -> 4.0–4.5 | G12: =IF('评分依据'!K35=0,"待评",TEXT('评分依据'!F35,"0.0")&"–"&TEXT('评分依据'!G35,"0.0")) -> 3.5–4.0 | H12: =IF('评分依据'!K47=0,"待评",TEXT('评分依据'!F47,"0.0")&"–"&TEXT('评分依据'!G47,"0.0")) -> 4.0–4.5 | I12: =IF('评分依据'!K59=0,"待评",TEXT('评分依据'!F59,"0.0")&"–"&TEXT('评分依据'!G59,"0.0")) -> 待评 | J12: =IF('评分依据'!K71=0,"待评",TEXT('评分依据'!F71,"0.0")&"–"&TEXT('评分依据'!G71,"0.0")) -> 待评
A13: G 大气与雾 | B13: 5 | C13: =IF('项目对照'!L15="有效",'项目对照'!D15,"") | D13: =IF(ISNUMBER('项目对照'!I15),'项目对照'!I15,"") -> 4 | E13: =IF('评分依据'!K12=0,"待评",TEXT('评分依据'!F12,"0.0")&"–"&TEXT('评分依据'!G12,"0.0")) -> 待评 | F13: =IF('评分依据'!K24=0,"待评",TEXT('评分依据'!F24,"0.0")&"–"&TEXT('评分依据'!G24,"0.0")) -> 4.0–4.5 | G13: =IF('评分依据'!K36=0,"待评",TEXT('评分依据'!F36,"0.0")&"–"&TEXT('评分依据'!G36,"0.0")) -> 4.5–5.0 | H13: =IF('评分依据'!K48=0,"待评",TEXT('评分依据'!F48,"0.0")&"–"&TEXT('评分依据'!G48,"0.0")) -> 4.0–4.5 | I13: =IF('评分依据'!K60=0,"待评",TEXT('评分依据'!F60,"0.0")&"–"&TEXT('评分依据'!G60,"0.0")) -> 待评 | J13: =IF('评分依据'!K72=0,"待评",TEXT('评分依据'!F72,"0.0")&"–"&TEXT('评分依据'!G72,"0.0")) -> 待评
A14: H 角色与动作呈现 | B14: 10 | C14: =IF('项目对照'!L16="有效",'项目对照'!D16,"") | D14: =IF(ISNUMBER('项目对照'!I16),'项目对照'!I16,"") -> 4.5 | E14: =IF('评分依据'!K13=0,"待评",TEXT('评分依据'!F13,"0.0")&"–"&TEXT('评分依据'!G13,"0.0")) -> 3.5–4.0 | F14: =IF('评分依据'!K25=0,"待评",TEXT('评分依据'!F25,"0.0")&"–"&TEXT('评分依据'!G25,"0.0")) -> 4.0–4.5 | G14: =IF('评分依据'!K37=0,"待评",TEXT('评分依据'!F37,"0.0")&"–"&TEXT('评分依据'!G37,"0.0")) -> 4.5–5.0 | H14: =IF('评分依据'!K49=0,"待评",TEXT('评分依据'!F49,"0.0")&"–"&TEXT('评分依据'!G49,"0.0")) -> 3.5–4.5 | I14: =IF('评分依据'!K61=0,"待评",TEXT('评分依据'!F61,"0.0")&"–"&TEXT('评分依据'!G61,"0.0")) -> 4.0–4.5 | J14: =IF('评分依据'!K73=0,"待评",TEXT('评分依据'!F73,"0.0")&"–"&TEXT('评分依据'!G73,"0.0")) -> 待评
A15: I 特效与战斗反馈 | B15: 8 | C15: =IF('项目对照'!L17="有效",'项目对照'!D17,"") | D15: =IF(ISNUMBER('项目对照'!I17),'项目对照'!I17,"") -> 4.5 | E15: =IF('评分依据'!K14=0,"待评",TEXT('评分依据'!F14,"0.0")&"–"&TEXT('评分依据'!G14,"0.0")) -> 待评 | F15: =IF('评分依据'!K26=0,"待评",TEXT('评分依据'!F26,"0.0")&"–"&TEXT('评分依据'!G26,"0.0")) -> 4.0–4.5 | G15: =IF('评分依据'!K38=0,"待评",TEXT('评分依据'!F38,"0.0")&"–"&TEXT('评分依据'!G38,"0.0")) -> 4.0–4.5 | H15: =IF('评分依据'!K50=0,"待评",TEXT('评分依据'!F50,"0.0")&"–"&TEXT('评分依据'!G50,"0.0")) -> 待评 | I15: =IF('评分依据'!K62=0,"待评",TEXT('评分依据'!F62,"0.0")&"–"&TEXT('评分依据'!G62,"0.0")) -> 4.0–4.5 | J15: =IF('评分依据'!K74=0,"待评",TEXT('评分依据'!F74,"0.0")&"–"&TEXT('评分依据'!G74,"0.0")) -> 待评
A16: J 运动画质与重建 | B16: 10 | C16: =IF('项目对照'!L18="有效",'项目对照'!D18,"") | D16: =IF(ISNUMBER('项目对照'!I18),'项目对照'!I18,"") -> 4 | E16: =IF('评分依据'!K15=0,"待评",TEXT('评分依据'!F15,"0.0")&"–"&TEXT('评分依据'!G15,"0.0")) -> 待评 | F16: =IF('评分依据'!K27=0,"待评",TEXT('评分依据'!F27,"0.0")&"–"&TEXT('评分依据'!G27,"0.0")) -> 3.0–4.0 | G16: =IF('评分依据'!K39=0,"待评",TEXT('评分依据'!F39,"0.0")&"–"&TEXT('评分依据'!G39,"0.0")) -> 4.0–4.5 | H16: =IF('评分依据'!K51=0,"待评",TEXT('评分依据'!F51,"0.0")&"–"&TEXT('评分依据'!G51,"0.0")) -> 3.0–4.0 | I16: =IF('评分依据'!K63=0,"待评",TEXT('评分依据'!F63,"0.0")&"–"&TEXT('评分依据'!G63,"0.0")) -> 4.0–4.5 | J16: =IF('评分依据'!K75=0,"待评",TEXT('评分依据'!F75,"0.0")&"–"&TEXT('评分依据'!G75,"0.0")) -> 待评
A17: K 后期与显示 | B17: 6 | C17: =IF('项目对照'!L19="有效",'项目对照'!D19,"") | D17: =IF(ISNUMBER('项目对照'!I19),'项目对照'!I19,"") -> 4 | E17: =IF('评分依据'!K16=0,"待评",TEXT('评分依据'!F16,"0.0")&"–"&TEXT('评分依据'!G16,"0.0")) -> 待评 | F17: =IF('评分依据'!K28=0,"待评",TEXT('评分依据'!F28,"0.0")&"–"&TEXT('评分依据'!G28,"0.0")) -> 待评 | G17: =IF('评分依据'!K40=0,"待评",TEXT('评分依据'!F40,"0.0")&"–"&TEXT('评分依据'!G40,"0.0")) -> 待评 | H17: =IF('评分依据'!K52=0,"待评",TEXT('评分依据'!F52,"0.0")&"–"&TEXT('评分依据'!G52,"0.0")) -> 待评 | I17: =IF('评分依据'!K64=0,"待评",TEXT('评分依据'!F64,"0.0")&"–"&TEXT('评分依据'!G64,"0.0")) -> 4.0–4.5 | J17: =IF('评分依据'!K76=0,"待评",TEXT('评分依据'!F76,"0.0")&"–"&TEXT('评分依据'!G76,"0.0")) -> 待评
A18: L 全流程一致性 | B18: 5 | C18: =IF('项目对照'!L20="有效",'项目对照'!D20,"") | D18: =IF(ISNUMBER('项目对照'!I20),'项目对照'!I20,"") -> 4 | E18: =IF('评分依据'!K17=0,"待评",TEXT('评分依据'!F17,"0.0")&"–"&TEXT('评分依据'!G17,"0.0")) -> 待评 | F18: =IF('评分依据'!K29=0,"待评",TEXT('评分依据'!F29,"0.0")&"–"&TEXT('评分依据'!G29,"0.0")) -> 3.0–4.0 | G18: =IF('评分依据'!K41=0,"待评",TEXT('评分依据'!F41,"0.0")&"–"&TEXT('评分依据'!G41,"0.0")) -> 4.0–4.5 | H18: =IF('评分依据'!K53=0,"待评",TEXT('评分依据'!F53,"0.0")&"–"&TEXT('评分依据'!G53,"0.0")) -> 待评 | I18: =IF('评分依据'!K65=0,"待评",TEXT('评分依据'!F65,"0.0")&"–"&TEXT('评分依据'!G65,"0.0")) -> 待评 | J18: =IF('评分依据'!K77=0,"待评",TEXT('评分依据'!F77,"0.0")&"–"&TEXT('评分依据'!G77,"0.0")) -> 待评
A20: 视觉基础指数下沿 / 100 | C20: =IF(ISNUMBER('项目对照'!D23),'项目对照'!D23,"") | D20: =IF(ISNUMBER('项目对照'!D26),SUMPRODUCT('项目对照'!I9:I20,'项目对照'!M9:M20)/5/52*100,"") -> 88.846154 | E20: =IF(SUM('评分依据'!K6,'评分依据'!K7,'评分依据'!K8,'评分依据'!K9,'评分依据'!K13)=52,('评分依据'!F6*'评分依据'!E6+'评分依据'!F7*'评分依据'!E7+'评分依据'!F8*'评分依据'!E8+'评分依据'!F9*'评分依据'!E9+'评分依据'!F13*'评分依据'!E13)/5/52*100,"") -> 78.076923 | F20: =IF(SUM('评分依据'!K18,'评分依据'!K19,'评分依据'!K20,'评分依据'!K21,'评分依据'!K25)=52,('评分依据'!F18*'评分依据'!E18+'评分依据'!F19*'评分依据'!E19+'评分依据'!F20*'评分依据'!E20+'评分依据'!F21*'评分依据'!E21+'评分依据'!F25*'评分依据'!E25)/5/52*100,"") -> 78.076923 | G20: =IF(SUM('评分依据'!K30,'评分依据'!K31,'评分依据'!K32,'评分依据'!K33,'评分依据'!K37)=52,('评分依据'!F30*'评分依据'!E30+'评分依据'!F31*'评分依据'!E31+'评分依据'!F32*'评分依据'!E32+'评分依据'!F33*'评分依据'!E33+'评分依据'!F37*'评分依据'!E37)/5/52*100,"") -> 90 | H20: =IF(SUM('评分依据'!K42,'评分依据'!K43,'评分依据'!K44,'评分依据'!K45,'评分依据'!K49)=52,('评分依据'!F42*'评分依据'!E42+'评分依据'!F43*'评分依据'!E43+'评分依据'!F44*'评分依据'!E44+'评分依据'!F45*'评分依据'!E45+'评分依据'!F49*'评分依据'!E49)/5/52*100,"") -> 76.153846 | I20: =IF(SUM('评分依据'!K54,'评分依据'!K55,'评分依据'!K56,'评分依据'!K57,'评分依据'!K61)=52,('评分依据'!F54*'评分依据'!E54+'评分依据'!F55*'评分依据'!E55+'评分依据'!F56*'评分依据'!E56+'评分依据'!F57*'评分依据'!E57+'评分依据'!F61*'评分依据'!E61)/5/52*100,"") -> 80 | J20: =IF(SUM('评分依据'!K66,'评分依据'!K67,'评分依据'!K68,'评分依据'!K69,'评分依据'!K73)=52,('评分依据'!F66*'评分依据'!E66+'评分依据'!F67*'评分依据'!E67+'评分依据'!F68*'评分依据'!E68+'评分依据'!F69*'评分依据'!E69+'评分依据'!F73*'评分依据'!E73)/5/52*100,"")
A21: 视觉基础指数上沿 / 100 | C21: =IF(ISNUMBER(C20),C20,"") | D21: =IF(ISNUMBER(D20),D20,"") -> 88.846154 | E21: =IF(SUM('评分依据'!K6,'评分依据'!K7,'评分依据'!K8,'评分依据'!K9,'评分依据'!K13)=52,('评分依据'!G6*'评分依据'!E6+'评分依据'!G7*'评分依据'!E7+'评分依据'!G8*'评分依据'!E8+'评分依据'!G9*'评分依据'!E9+'评分依据'!G13*'评分依据'!E13)/5/52*100,"") -> 88.076923 | F21: =IF(SUM('评分依据'!K18,'评分依据'!K19,'评分依据'!K20,'评分依据'!K21,'评分依据'!K25)=52,('评分依据'!G18*'评分依据'!E18+'评分依据'!G19*'评分依据'!E19+'评分依据'!G20*'评分依据'!E20+'评分依据'!G21*'评分依据'!E21+'评分依据'!G25*'评分依据'!E25)/5/52*100,"") -> 90 | G21: =IF(SUM('评分依据'!K30,'评分依据'!K31,'评分依据'!K32,'评分依据'!K33,'评分依据'!K37)=52,('评分依据'!G30*'评分依据'!E30+'评分依据'!G31*'评分依据'!E31+'评分依据'!G32*'评分依据'!E32+'评分依据'!G33*'评分依据'!E33+'评分依据'!G37*'评分依据'!E37)/5/52*100,"") -> 100 | H21: =IF(SUM('评分依据'!K42,'评分依据'!K43,'评分依据'!K44,'评分依据'!K45,'评分依据'!K49)=52,('评分依据'!G42*'评分依据'!E42+'评分依据'!G43*'评分依据'!E43+'评分依据'!G44*'评分依据'!E44+'评分依据'!G45*'评分依据'!E45+'评分依据'!G49*'评分依据'!E49)/5/52*100,"") -> 90 | I21: =IF(SUM('评分依据'!K54,'评分依据'!K55,'评分依据'!K56,'评分依据'!K57,'评分依据'!K61)=52,('评分依据'!G54*'评分依据'!E54+'评分依据'!G55*'评分依据'!E55+'评分依据'!G56*'评分依据'!E56+'评分依据'!G57*'评分依据'!E57+'评分依据'!G61*'评分依据'!E61)/5/52*100,"") -> 90 | J21: =IF(SUM('评分依据'!K66,'评分依据'!K67,'评分依据'!K68,'评分依据'!K69,'评分依据'!K73)=52,('评分依据'!G66*'评分依据'!E66+'评分依据'!G67*'评分依据'!E67+'评分依据'!G68*'评分依据'!E68+'评分依据'!G69*'评分依据'!E69+'评分依据'!G73*'评分依据'!E73)/5/52*100,"")
A22: 类别覆盖权重 | C22: =SUMIFS('项目对照'!C9:C20,'项目对照'!L9:L20,"有效")/100 -> 0 | D22: 1 | E22: =SUM('评分依据'!K6:K17)/100 -> 0.52 | F22: =SUM('评分依据'!K18:K29)/100 -> 0.94 | G22: =SUM('评分依据'!K30:K41)/100 -> 0.94 | H22: =SUM('评分依据'!K42:K53)/100 -> 0.73 | I22: =SUM('评分依据'!K54:K65)/100 -> 0.84 | J22: =SUM('评分依据'!K66:K77)/100 -> 0
A23: 12类初评下沿 / 100 | C23: =IF(ISNUMBER('项目对照'!D25),'项目对照'!D25,"") | D23: =IF(ISNUMBER('项目对照'!D26),'项目对照'!D26,"") -> 85.4 | E23: =IF(E22=1,SUMPRODUCT('评分依据'!E6:E17,'评分依据'!F6:F17)/5,"") | F23: =IF(F22=1,SUMPRODUCT('评分依据'!E18:E29,'评分依据'!F18:F29)/5,"") | G23: =IF(G22=1,SUMPRODUCT('评分依据'!E30:E41,'评分依据'!F30:F41)/5,"") | H23: =IF(H22=1,SUMPRODUCT('评分依据'!E42:E53,'评分依据'!F42:F53)/5,"") | I23: =IF(I22=1,SUMPRODUCT('评分依据'!E54:E65,'评分依据'!F54:F65)/5,"") | J23: =IF(J22=1,SUMPRODUCT('评分依据'!E66:E77,'评分依据'!F66:F77)/5,"")
A24: 12类初评上沿 / 100 | C24: =IF(ISNUMBER(C23),C23,"") | D24: =IF(ISNUMBER(D23),D23,"") -> 85.4 | E24: =IF(E22=1,SUMPRODUCT('评分依据'!E6:E17,'评分依据'!G6:G17)/5,"") | F24: =IF(F22=1,SUMPRODUCT('评分依据'!E18:E29,'评分依据'!G18:G29)/5,"") | G24: =IF(G22=1,SUMPRODUCT('评分依据'!E30:E41,'评分依据'!G30:G41)/5,"") | H24: =IF(H22=1,SUMPRODUCT('评分依据'!E42:E53,'评分依据'!G42:G53)/5,"") | I24: =IF(I22=1,SUMPRODUCT('评分依据'!E54:E65,'评分依据'!G54:G65)/5,"") | J24: =IF(J22=1,SUMPRODUCT('评分依据'!E66:E77,'评分依据'!G66:G77)/5,"")
A27: 视觉基础指数只覆盖 A/B/C/D/H，合计52%原权重；不代表整体商品水平。
A28: 类别覆盖不等于60项已验收。12类初评齐全才计算区间，缺项不按零分处理。
A29: PC与Xbox样本用于画质方向参考；PS5交付方案须补同平台、同Build、同模式实测。
A30: 建议目标是项目内部提案。画质优先时，可并列评审60/40/30模式及各自视觉收益。
A32: 优先参考 | B32: Delta：题材与重制呈现；悟空：动作场景光照；Hellblade II：角色、自然光和大气。
B33: 寂静岭2：暗部与雾；恶魔之魂：历史美术完成度；影之刃零：等待终版复测。

Sheet 项目对照
A2: 本项目录入与差距
A4: 对标样本 | B4: 合金装备Delta：食蛇者
A5: 本项目Build | D5: 平台 / 模式
A6: 样本口径 | B6: {=INDEX('样本与方法'!$C$7:$C$12,MATCH(B4,'样本与方法'!$A$7:$A$12,0))} -> PC Ultra，2025首发窗口；结构/动画辅以预设未明的PC评测
A8: 编号 | B8: 维度 | C8: 权重 | D8: 项目分 / 5 | E8: 参考下沿 | F8: 参考上沿 | G8: 项目－参考下沿 | H8: 项目－参考上沿 | I8: 建议目标 / 5 | J8: 到目标可增分 | K8: 项目证据 / 待办 | L8: 输入状态 | M8: 基础指数权重
A9: A | B9: 整体视觉设计 | C9: 6 | E9: =IF(COUNTIFS('评分依据'!$B$6:$B$77,$B$4,'评分依据'!$C$6:$C$77,A9,'评分依据'!$K$6:$K$77,">0")=0,"",SUMIFS('评分依据'!$F$6:$F$77,'评分依据'!$B$6:$B$77,$B$4,'评分依据'!$C$6:$C$77,A9)) -> 4 | F9: =IF(ISNUMBER(E9),SUMIFS('评分依据'!$G$6:$G$77,'评分依据'!$B$6:$B$77,$B$4,'评分依据'!$C$6:$C$77,A9),"") -> 4.5 | G9: =IF(AND(L9="有效",ISNUMBER(E9)),D9-E9,"") | H9: =IF(AND(L9="有效",ISNUMBER(F9)),D9-F9,"") | I9: 4 | J9: =IF(AND(L9="有效",ISNUMBER(I9),I9>=0,I9<=5),MAX(0,I9-D9)/5*C9,"") | L9: =IF(ISNUMBER(D9),IF(AND(D9>=0,D9<=5),"有效","请填0–5"),IF(D9="","待填","请填0–5")) -> 待填 | M9: 6
A10: B | B10: 场景与几何 | C10: 12 | E10: =IF(COUNTIFS('评分依据'!$B$6:$B$77,$B$4,'评分依据'!$C$6:$C$77,A10,'评分依据'!$K$6:$K$77,">0")=0,"",SUMIFS('评分依据'!$F$6:$F$77,'评分依据'!$B$6:$B$77,$B$4,'评分依据'!$C$6:$C$77,A10)) -> 4 | F10: =IF(ISNUMBER(E10),SUMIFS('评分依据'!$G$6:$G$77,'评分依据'!$B$6:$B$77,$B$4,'评分依据'!$C$6:$C$77,A10),"") -> 4.5 | G10: =IF(AND(L10="有效",ISNUMBER(E10)),D10-E10,"") | H10: =IF(AND(L10="有效",ISNUMBER(F10)),D10-F10,"") | I10: 4.5 | J10: =IF(AND(L10="有效",ISNUMBER(I10),I10>=0,I10<=5),MAX(0,I10-D10)/5*C10,"") | L10: =IF(ISNUMBER(D10),IF(AND(D10>=0,D10<=5),"有效","请填0–5"),IF(D10="","待填","请填0–5")) -> 待填 | M10: 12
A11: C | B11: 材质与纹理 | C11: 10 | E11: =IF(COUNTIFS('评分依据'!$B$6:$B$77,$B$4,'评分依据'!$C$6:$C$77,A11,'评分依据'!$K$6:$K$77,">0")=0,"",SUMIFS('评分依据'!$F$6:$F$77,'评分依据'!$B$6:$B$77,$B$4,'评分依据'!$C$6:$C$77,A11)) -> 4 | F11: =IF(ISNUMBER(E11),SUMIFS('评分依据'!$G$6:$G$77,'评分依据'!$B$6:$B$77,$B$4,'评分依据'!$C$6:$C$77,A11),"") -> 4.5 | G11: =IF(AND(L11="有效",ISNUMBER(E11)),D11-E11,"") | H11: =IF(AND(L11="有效",ISNUMBER(F11)),D11-F11,"") | I11: 4.5 | J11: =IF(AND(L11="有效",ISNUMBER(I11),I11>=0,I11<=5),MAX(0,I11-D11)/5*C11,"") | L11: =IF(ISNUMBER(D11),IF(AND(D11>=0,D11<=5),"有效","请填0–5"),IF(D11="","待填","请填0–5")) -> 待填 | M11: 10
A12: D | B12: 灯光与间接光 | C12: 14 | E12: =IF(COUNTIFS('评分依据'!$B$6:$B$77,$B$4,'评分依据'!$C$6:$C$77,A12,'评分依据'!$K$6:$K$77,">0")=0,"",SUMIFS('评分依据'!$F$6:$F$77,'评分依据'!$B$6:$B$77,$B$4,'评分依据'!$C$6:$C$77,A12)) -> 4 | F12: =IF(ISNUMBER(E12),SUMIFS('评分依据'!$G$6:$G$77,'评分依据'!$B$6:$B$77,$B$4,'评分依据'!$C$6:$C$77,A12),"") -> 4.5 | G12: =IF(AND(L12="有效",ISNUMBER(E12)),D12-E12,"") | H12: =IF(AND(L12="有效",ISNUMBER(F12)),D12-F12,"") | I12: 4.5 | J12: =IF(AND(L12="有效",ISNUMBER(I12),I12>=0,I12<=5),MAX(0,I12-D12)/5*C12,"") | L12: =IF(ISNUMBER(D12),IF(AND(D12>=0,D12<=5),"有效","请填0–5"),IF(D12="","待填","请填0–5")) -> 待填 | M12: 14
A13: E | B13: 阴影与接触关系 | C13: 8 | E13: =IF(COUNTIFS('评分依据'!$B$6:$B$77,$B$4,'评分依据'!$C$6:$C$77,A13,'评分依据'!$K$6:$K$77,">0")=0,"",SUMIFS('评分依据'!$F$6:$F$77,'评分依据'!$B$6:$B$77,$B$4,'评分依据'!$C$6:$C$77,A13)) | F13: =IF(ISNUMBER(E13),SUMIFS('评分依据'!$G$6:$G$77,'评分依据'!$B$6:$B$77,$B$4,'评分依据'!$C$6:$C$77,A13),"") | G13: =IF(AND(L13="有效",ISNUMBER(E13)),D13-E13,"") | H13: =IF(AND(L13="有效",ISNUMBER(F13)),D13-F13,"") | I13: 4 | J13: =IF(AND(L13="有效",ISNUMBER(I13),I13>=0,I13<=5),MAX(0,I13-D13)/5*C13,"") | L13: =IF(ISNUMBER(D13),IF(AND(D13>=0,D13<=5),"有效","请填0–5"),IF(D13="","待填","请填0–5")) -> 待填 | M13: 0
A14: F | B14: 反射与环境照明输入 | C14: 6 | E14: =IF(COUNTIFS('评分依据'!$B$6:$B$77,$B$4,'评分依据'!$C$6:$C$77,A14,'评分依据'!$K$6:$K$77,">0")=0,"",SUMIFS('评分依据'!$F$6:$F$77,'评分依据'!$B$6:$B$77,$B$4,'评分依据'!$C$6:$C$77,A14)) | F14: =IF(ISNUMBER(E14),SUMIFS('评分依据'!$G$6:$G$77,'评分依据'!$B$6:$B$77,$B$4,'评分依据'!$C$6:$C$77,A14),"") | G14: =IF(AND(L14="有效",ISNUMBER(E14)),D14-E14,"") | H14: =IF(AND(L14="有效",ISNUMBER(F14)),D14-F14,"") | I14: 4 | J14: =IF(AND(L14="有效",ISNUMBER(I14),I14>=0,I14<=5),MAX(0,I14-D14)/5*C14,"") | L14: =IF(ISNUMBER(D14),IF(AND(D14>=0,D14<=5),"有效","请填0–5"),IF(D14="","待填","请填0–5")) -> 待填 | M14: 0
A15: G | B15: 大气与雾 | C15: 5 | E15: =IF(COUNTIFS('评分依据'!$B$6:$B$77,$B$4,'评分依据'!$C$6:$C$77,A15,'评分依据'!$K$6:$K$77,">0")=0,"",SUMIFS('评分依据'!$F$6:$F$77,'评分依据'!$B$6:$B$77,$B$4,'评分依据'!$C$6:$C$77,A15)) | F15: =IF(ISNUMBER(E15),SUMIFS('评分依据'!$G$6:$G$77,'评分依据'!$B$6:$B$77,$B$4,'评分依据'!$C$6:$C$77,A15),"") | G15: =IF(AND(L15="有效",ISNUMBER(E15)),D15-E15,"") | H15: =IF(AND(L15="有效",ISNUMBER(F15)),D15-F15,"") | I15: 4 | J15: =IF(AND(L15="有效",ISNUMBER(I15),I15>=0,I15<=5),MAX(0,I15-D15)/5*C15,"") | L15: =IF(ISNUMBER(D15),IF(AND(D15>=0,D15<=5),"有效","请填0–5"),IF(D15="","待填","请填0–5")) -> 待填 | M15: 0
A16: H | B16: 角色与动作呈现 | C16: 10 | E16: =IF(COUNTIFS('评分依据'!$B$6:$B$77,$B$4,'评分依据'!$C$6:$C$77,A16,'评分依据'!$K$6:$K$77,">0")=0,"",SUMIFS('评分依据'!$F$6:$F$77,'评分依据'!$B$6:$B$77,$B$4,'评分依据'!$C$6:$C$77,A16)) -> 3.5 | F16: =IF(ISNUMBER(E16),SUMIFS('评分依据'!$G$6:$G$77,'评分依据'!$B$6:$B$77,$B$4,'评分依据'!$C$6:$C$77,A16),"") -> 4 | G16: =IF(AND(L16="有效",ISNUMBER(E16)),D16-E16,"") | H16: =IF(AND(L16="有效",ISNUMBER(F16)),D16-F16,"") | I16: 4.5 | J16: =IF(AND(L16="有效",ISNUMBER(I16),I16>=0,I16<=5),MAX(0,I16-D16)/5*C16,"") | L16: =IF(ISNUMBER(D16),IF(AND(D16>=0,D16<=5),"有效","请填0–5"),IF(D16="","待填","请填0–5")) -> 待填 | M16: 10
A17: I | B17: 特效与战斗反馈 | C17: 8 | E17: =IF(COUNTIFS('评分依据'!$B$6:$B$77,$B$4,'评分依据'!$C$6:$C$77,A17,'评分依据'!$K$6:$K$77,">0")=0,"",SUMIFS('评分依据'!$F$6:$F$77,'评分依据'!$B$6:$B$77,$B$4,'评分依据'!$C$6:$C$77,A17)) | F17: =IF(ISNUMBER(E17),SUMIFS('评分依据'!$G$6:$G$77,'评分依据'!$B$6:$B$77,$B$4,'评分依据'!$C$6:$C$77,A17),"") | G17: =IF(AND(L17="有效",ISNUMBER(E17)),D17-E17,"") | H17: =IF(AND(L17="有效",ISNUMBER(F17)),D17-F17,"") | I17: 4.5 | J17: =IF(AND(L17="有效",ISNUMBER(I17),I17>=0,I17<=5),MAX(0,I17-D17)/5*C17,"") | L17: =IF(ISNUMBER(D17),IF(AND(D17>=0,D17<=5),"有效","请填0–5"),IF(D17="","待填","请填0–5")) -> 待填 | M17: 0
A18: J | B18: 运动画质与重建 | C18: 10 | E18: =IF(COUNTIFS('评分依据'!$B$6:$B$77,$B$4,'评分依据'!$C$6:$C$77,A18,'评分依据'!$K$6:$K$77,">0")=0,"",SUMIFS('评分依据'!$F$6:$F$77,'评分依据'!$B$6:$B$77,$B$4,'评分依据'!$C$6:$C$77,A18)) | F18: =IF(ISNUMBER(E18),SUMIFS('评分依据'!$G$6:$G$77,'评分依据'!$B$6:$B$77,$B$4,'评分依据'!$C$6:$C$77,A18),"") | G18: =IF(AND(L18="有效",ISNUMBER(E18)),D18-E18,"") | H18: =IF(AND(L18="有效",ISNUMBER(F18)),D18-F18,"") | I18: 4 | J18: =IF(AND(L18="有效",ISNUMBER(I18),I18>=0,I18<=5),MAX(0,I18-D18)/5*C18,"") | L18: =IF(ISNUMBER(D18),IF(AND(D18>=0,D18<=5),"有效","请填0–5"),IF(D18="","待填","请填0–5")) -> 待填 | M18: 0
A19: K | B19: 后期与显示 | C19: 6 | E19: =IF(COUNTIFS('评分依据'!$B$6:$B$77,$B$4,'评分依据'!$C$6:$C$77,A19,'评分依据'!$K$6:$K$77,">0")=0,"",SUMIFS('评分依据'!$F$6:$F$77,'评分依据'!$B$6:$B$77,$B$4,'评分依据'!$C$6:$C$77,A19)) | F19: =IF(ISNUMBER(E19),SUMIFS('评分依据'!$G$6:$G$77,'评分依据'!$B$6:$B$77,$B$4,'评分依据'!$C$6:$C$77,A19),"") | G19: =IF(AND(L19="有效",ISNUMBER(E19)),D19-E19,"") | H19: =IF(AND(L19="有效",ISNUMBER(F19)),D19-F19,"") | I19: 4 | J19: =IF(AND(L19="有效",ISNUMBER(I19),I19>=0,I19<=5),MAX(0,I19-D19)/5*C19,"") | L19: =IF(ISNUMBER(D19),IF(AND(D19>=0,D19<=5),"有效","请填0–5"),IF(D19="","待填","请填0–5")) -> 待填 | M19: 0
A20: L | B20: 全流程一致性 | C20: 5 | E20: =IF(COUNTIFS('评分依据'!$B$6:$B$77,$B$4,'评分依据'!$C$6:$C$77,A20,'评分依据'!$K$6:$K$77,">0")=0,"",SUMIFS('评分依据'!$F$6:$F$77,'评分依据'!$B$6:$B$77,$B$4,'评分依据'!$C$6:$C$77,A20)) | F20: =IF(ISNUMBER(E20),SUMIFS('评分依据'!$G$6:$G$77,'评分依据'!$B$6:$B$77,$B$4,'评分依据'!$C$6:$C$77,A20),"") | G20: =IF(AND(L20="有效",ISNUMBER(E20)),D20-E20,"") | H20: =IF(AND(L20="有效",ISNUMBER(F20)),D20-F20,"") | I20: 4 | J20: =IF(AND(L20="有效",ISNUMBER(I20),I20>=0,I20<=5),MAX(0,I20-D20)/5*C20,"") | L20: =IF(ISNUMBER(D20),IF(AND(D20>=0,D20<=5),"有效","请填0–5"),IF(D20="","待填","请填0–5")) -> 待填 | M20: 0
A23: 项目视觉基础指数 / 100 | D23: =IF(COUNTIFS(L9:L20,"有效",M9:M20,">0")=5,SUMPRODUCT(D9:D20,M9:M20)/5/SUM(M9:M20)*100,"")
A24: 已填类别数 / 12 | D24: =COUNTIFS(L9:L20,"有效") -> 0
A25: 项目12类汇总 / 100 | D25: =IF(COUNTIFS(L9:L20,"有效")=12,SUMPRODUCT(C9:C20,D9:D20)/5,"")
A26: 建议目标汇总 / 100 | D26: =IF(COUNT(I9:I20)=12,IF(AND(MIN(I9:I20)>=0,MAX(I9:I20)<=5),SUMPRODUCT(C9:C20,I9:I20)/5,""),"") -> 85.4
A27: 到目标可增分（已填部分） | D27: =IF(COUNT(J9:J20)=0,"",SUM(J9:J20))
A29: 使用顺序：先填Build和模式，再从原60项表转入类别均分；选择对标样本看差距。
A30: 参考区间重叠时，不据此判断谁一定更好。空白参考项没有参与差距计算。
A31: 汇总值不自动授予S/A等级；正式评级还要核验60项证据、视觉底线和该模式交付条件。

Sheet 评分依据
A2: 参考区间与原始依据
A4: 数值为本报告的桌面初评；媒体未提供这些单项分数。空白表示该样本缺少足够依据。
A5: 样本-类别 | B5: 游戏 | C5: 类目 | D5: 维度 | E5: 原权重 | F5: 下沿 / 5 | G5: 上沿 / 5 | H5: 评分依据（简述） | I5: 来源编号 | J5: 适用范围 / 待补 | K5: 本类覆盖权重
A6: DELTA-A | B6: 合金装备Delta：食蛇者 | C6: A | D6: 整体视觉设计 | E6: 6 | F6: 4 | G6: 4.5 | H6: 整体重制完成度高 | I6: D-CB1 / DELTA_DSO | J6: 方向性初评，尚未按60项实机复验 | K6: =IF(COUNT(F6:G6)=2,E6,0) -> 6
A7: DELTA-B | B7: 合金装备Delta：食蛇者 | C7: B | D7: 场景与几何 | E7: 12 | F7: 4 | G7: 4.5 | H7: 环境细节与植被丰富 | I7: DELTA_GR / D-CB1 | J7: PC场景组织；GR预设未注明，不能用来推断Ultra的全部几何稳定性 | K7: =IF(COUNT(F7:G7)=2,E7,0) -> 12
A8: DELTA-C | B8: 合金装备Delta：食蛇者 | C8: C | D8: 材质与纹理 | E8: 10 | F8: 4 | G8: 4.5 | H8: 大量高分辨率纹理 | I8: DELTA_DSO | J8: 没有具体贴图尺寸；多光照材质响应仍待核验 | K8: =IF(COUNT(F8:G8)=2,E8,0) -> 10
A9: DELTA-D | B9: 合金装备Delta：食蛇者 | C9: D | D9: 灯光与间接光 | E9: 14 | F9: 4 | G9: 4.5 | H9: 照明一致；降档会减弱层次 | I9: DELTA_DSO / D-CB2 | J9: PC Ultra；不转填基础PS5 | K9: =IF(COUNT(F9:G9)=2,E9,0) -> 14
A10: DELTA-E | B10: 合金装备Delta：食蛇者 | C10: E | D10: 阴影与接触关系 | E10: 8 | H10: 预设变化会影响阴影，但缺少接触关系专项评价 | I10: D-CB2 | J10: 待补同版本实机录像和专项检查 | K10: =IF(COUNT(F10:G10)=2,E10,0) -> 0
A11: DELTA-F | B11: 合金装备Delta：食蛇者 | C11: F | D11: 反射与环境照明输入 | E11: 6 | H11: 能确认反射路径，缺少完整结果评价 | I11: D-CB1 | J11: 待补同版本实机录像和专项检查 | K11: =IF(COUNT(F11:G11)=2,E11,0) -> 0
A12: DELTA-G | B12: 合金装备Delta：食蛇者 | C12: G | D12: 大气与雾 | E12: 5 | H12: 没有足够的成品分项评测 | J12: 待补同版本实机录像和专项检查 | K12: =IF(COUNT(F12:G12)=2,E12,0) -> 0
A13: DELTA-H | B13: 合金装备Delta：食蛇者 | C13: H | D13: 角色与动作呈现 | E13: 10 | F13: 3.5 | G13: 4 | H13: 模型好；面部与动作有短板 | I13: D-CB1 / DELTA_GR / DELTA_DSO | J13: 动作问题不因高分辨率角色模型而被抵消 | K13: =IF(COUNT(F13:G13)=2,E13,0) -> 10
A14: DELTA-I | B14: 合金装备Delta：食蛇者 | C14: I | D14: 特效与战斗反馈 | E14: 8 | H14: 没有足够的成品分项评测 | J14: 待补同版本实机录像和专项检查 | K14: =IF(COUNT(F14:G14)=2,E14,0) -> 0
A15: DELTA-J | B15: 合金装备Delta：食蛇者 | C15: J | D15: 运动画质与重建 | E15: 10 | H15: 帧时间资料不能单独替代重建画质评价 | I15: D-CB2 | J15: 待补同版本实机录像和专项检查 | K15: =IF(COUNT(F15:G15)=2,E15,0) -> 0
A16: DELTA-K | B16: 合金装备Delta：食蛇者 | C16: K | D16: 后期与显示 | E16: 6 | H16: 支持HDR，不代表已验证显示效果 | I16: D-CB1 | J16: 待补同版本实机录像和专项检查 | K16: =IF(COUNT(F16:G16)=2,E16,0) -> 0
A17: DELTA-L | B17: 合金装备Delta：食蛇者 | C17: L | D17: 全流程一致性 | E17: 5 | H17: 有游玩/演出连续性评价，未完成长时与压力检查 | I17: D-CB1 | J17: 待补同版本实机录像和专项检查 | K17: =IF(COUNT(F17:G17)=2,E17,0) -> 0
A18: WUKONG-A | B18: 黑神话：悟空 | C18: A | D18: 整体视觉设计 | E18: 6 | F18: 4 | G18: 4.5 | H18: 主题与效果协调 | I18: WK_DF_PC_FULL / WK_CB4 | J18: PC高端历史样本整类方向性初评；非五子项全部验收 | K18: =IF(COUNT(F18:G18)=2,E18,0) -> 6
A19: WUKONG-B | B19: 黑神话：悟空 | C19: B | D19: 场景与几何 | E19: 12 | F19: 4 | G19: 4.5 | H19: 主体细节强；植被仍有跳变 | I19: WK_DF_PC_FULL / WK_CB3 | J19: PC高端历史样本整类方向性初评 | K19: =IF(COUNT(F19:G19)=2,E19,0) -> 12
A20: WUKONG-C | B20: 黑神话：悟空 | C20: C | D20: 材质与纹理 | E20: 10 | F20: 3.5 | G20: 4.5 | H20: 角色纹理好；部分环境纹理有缺陷 | I20: WK_DF_PC_FULL / WK_DSO_PC | J20: PC高端历史样本整类方向性初评；区间较宽体现覆盖不足 | K20: =IF(COUNT(F20:G20)=2,E20,0) -> 10
A21: WUKONG-D | B21: 黑神话：悟空 | C21: D | D21: 灯光与间接光 | E21: 14 | F21: 4 | G21: 4.5 | H21: Full RT改善光照关系 | I21: WK_CB2 | J21: PC Full RT Ultra、文章所示样本；内部推估 | K21: =IF(COUNT(F21:G21)=2,E21,0) -> 14
A22: WUKONG-E | B22: 黑神话：悟空 | C22: E | D22: 阴影与接触关系 | E22: 8 | F22: 4 | G22: 4.5 | H22: Full RT减少阴影闪烁 | I22: WK_CB1 / WK_CB2 | J22: PC Full RT Ultra阴影/遮挡子项；非独立AO配置分 | K22: =IF(COUNT(F22:G22)=2,E22,0) -> 8
A23: WUKONG-F | B23: 黑神话：悟空 | C23: F | D23: 反射与环境照明输入 | E23: 6 | F23: 4 | G23: 4.5 | H23: Full RT补充离屏反射 | I23: WK_CB2 | J23: 仅反射子项；不能推断8K HDRI | K23: =IF(COUNT(F23:G23)=2,E23,0) -> 6
A24: WUKONG-G | B24: 黑神话：悟空 | C24: G | D24: 大气与雾 | E24: 5 | F24: 4 | G24: 4.5 | H24: 开场雾可受动作扰动 | I24: WK_DF_PC_FULL | J24: 仅方向性参考；互动雾强项来自开场，普通路线与快速转镜待补 | K24: =IF(COUNT(F24:G24)=2,E24,0) -> 5
A25: WUKONG-H | B25: 黑神话：悟空 | C25: H | D25: 角色与动作呈现 | E25: 10 | F25: 4 | G25: 4.5 | H25: 敌人细节与次级动画丰富 | I25: WK_DF_PC_FULL / WK_DSO_PC | J25: PC高端历史样本整类方向性初评 | K25: =IF(COUNT(F25:G25)=2,E25,0) -> 10
A26: WUKONG-I | B26: 黑神话：悟空 | C26: I | D26: 特效与战斗反馈 | E26: 8 | F26: 4 | G26: 4.5 | H26: 粒子参与预兆与击败反馈 | I26: WK_DF_PC_FULL | J26: 已有视觉反馈证据；多敌人/技能叠加遮挡与负荷未验 | K26: =IF(COUNT(F26:G26)=2,E26,0) -> 8
A27: WUKONG-J | B27: 黑神话：悟空 | C27: J | D27: 运动画质与重建 | E27: 10 | F27: 3 | G27: 4 | H27: DLSS细植被仍闪；穿区卡顿 | I27: WK_CB1 / WK_CB3 | J27: PC DLSS 2024历史样本；未平均FSR/TSR，也未代填2026改善 | K27: =IF(COUNT(F27:G27)=2,E27,0) -> 10
A28: WUKONG-K | B28: 黑神话：悟空 | C28: K | D28: 后期与显示 | E28: 6 | H28: 缺少曝光与HDR专项评价 | I28: WK_DF_PC_FULL / WK_DSO_PC | J28: 已见景深和运动模糊观察；避免与J重建缺陷重复扣分 | K28: =IF(COUNT(F28:G28)=2,E28,0) -> 0
A29: WUKONG-L | B29: 黑神话：悟空 | C29: L | D29: 全流程一致性 | E29: 5 | F29: 3 | G29: 4 | H29: 场景之间完成度有起伏 | I29: WK_CB3 / WK_CB4 | J29: 仅指章节观感起伏；不把J的穿区卡顿再次计入扣分 | K29: =IF(COUNT(F29:G29)=2,E29,0) -> 5
A30: HELLBLADE-A | B30: 地狱之刃2：塞娜的史诗 | C30: A | D30: 整体视觉设计 | E30: 6 | F30: 4.5 | G30: 5 | H30: 镜头与画面风格统一 | I30: HB_DF_FULL_2024 / HB_INTERVIEW | J30: 上沿5分仍须压力场景验证 | K30: =IF(COUNT(F30:G30)=2,E30,0) -> 6
A31: HELLBLADE-B | B31: 地狱之刃2：塞娜的史诗 | C31: B | D31: 场景与几何 | E31: 12 | F31: 4.5 | G31: 5 | H31: 几何密度高，切换稳定 | I31: HB_DF_FULL_2024 | J31: 极近距离原始资产仍有局限 | K31: =IF(COUNT(F31:G31)=2,E31,0) -> 12
A32: HELLBLADE-C | B32: 地狱之刃2：塞娜的史诗 | C32: C | D32: 材质与纹理 | E32: 10 | F32: 4.5 | G32: 5 | H32: 皮肤和表面细节突出 | I32: HB_DF_FULL_2024 | J32: 环境材料跨光照一致性未全面量测 | K32: =IF(COUNT(F32:G32)=2,E32,0) -> 10
A33: HELLBLADE-D | B33: 地狱之刃2：塞娜的史诗 | C33: D | D33: 灯光与间接光 | E33: 14 | F33: 4.5 | G33: 5 | H33: 自然光与间接光可信 | I33: HB_DF_FULL_2024 | J33: 动态GI全场景收敛未复验 | K33: =IF(COUNT(F33:G33)=2,E33,0) -> 14
A34: HELLBLADE-E | B34: 地狱之刃2：塞娜的史诗 | C34: E | D34: 阴影与接触关系 | E34: 8 | F34: 4.5 | G34: 5 | H34: 小物阴影与遮蔽精细 | I34: HB_DF_FULL_2024 | J34: 跳跃/斜坡接触仍需独立检查 | K34: =IF(COUNT(F34:G34)=2,E34,0) -> 8
A35: HELLBLADE-F | B35: 地狱之刃2：塞娜的史诗 | C35: F | D35: 反射与环境照明输入 | E35: 6 | F35: 3.5 | G35: 4 | H35: 动态火把反射有SSR缺陷 | I35: HB_DF_FULL_2024 | J35: 不能把此例外推为全部反射失效 | K35: =IF(COUNT(F35:G35)=2,E35,0) -> 6
A36: HELLBLADE-G | B36: 地狱之刃2：塞娜的史诗 | C36: G | D36: 大气与雾 | E36: 5 | F36: 4.5 | G36: 5 | H36: 雾云烟融合，噪点少 | I36: HB_DF_FULL_2024 | J36: 不是用雾量大小评分 | K36: =IF(COUNT(F36:G36)=2,E36,0) -> 5
A37: HELLBLADE-H | B37: 地狱之刃2：塞娜的史诗 | C37: H | D37: 角色与动作呈现 | E37: 10 | F37: 4.5 | G37: 5 | H37: 面部、眼睛与微表情突出 | I37: HB_DF_FULL_2024 | J37: 不以受控叙事镜头代替高速动作全部要求 | K37: =IF(COUNT(F37:G37)=2,E37,0) -> 10
A38: HELLBLADE-I | B38: 地狱之刃2：塞娜的史诗 | C38: I | D38: 特效与战斗反馈 | E38: 8 | F38: 4 | G38: 4.5 | H38: 雨水海浪与流动效果成熟 | I38: HB_DF_FULL_2024 | J38: 环境效果强；高速群战反馈另验 | K38: =IF(COUNT(F38:G38)=2,E38,0) -> 8
A39: HELLBLADE-J | B39: 地狱之刃2：塞娜的史诗 | C39: J | D39: 运动画质与重建 | E39: 10 | F39: 4 | G39: 4.5 | H39: 画面偏柔，原版30节奏稳定 | I39: HB_DF_FULL_2024 | J39: 30fps本身不扣分；没有单独输入延迟量测 | K39: =IF(COUNT(F39:G39)=2,E39,0) -> 10
A40: HELLBLADE-K | B40: 地狱之刃2：塞娜的史诗 | C40: K | D40: 后期与显示 | E40: 6 | H40: 电影镜头效果好；HDR待验 | I40: HB_DF_FULL_2024 / HB_INTERVIEW | J40: 缺少完整曝光、HDR显示校准分析 | K40: =IF(COUNT(F40:G40)=2,E40,0) -> 0
A41: HELLBLADE-L | B41: 地狱之刃2：塞娜的史诗 | C41: L | D41: 全流程一致性 | E41: 5 | F41: 4 | G41: 4.5 | H41: 主要体验的呈现持续稳定 | I41: HB_DF_FULL_2024 | J41: 长时回访、异常操作与所有章节未按本表重跑 | K41: =IF(COUNT(F41:G41)=2,E41,0) -> 5
A42: SH2-A | B42: 寂静岭2重制版 | C42: A | D42: 整体视觉设计 | E42: 6 | F42: 4 | G42: 4.5 | H42: 恐怖氛围和重制空间的视觉表达一致。 | I42: SH_DF / SH_TR | J42: 美术方向优异不等于所有技术项顶级。 | K42: =IF(COUNT(F42:G42)=2,E42,0) -> 6
...

Sheet 样本与方法
A2: 样本边界与评分方法
A4: 资料整理：2026-10-12。评分是指定旧版样本的参考，不能代表所有平台或当前补丁。
A6: 游戏 | B6: 纳入范围 | C6: 评测样本 | D6: 评测日期 | E6: 后续变化 | F6: 适合借鉴 | G6: 来源编号
A7: 合金装备Delta：食蛇者 | B7: 2025｜UE5｜已发售 | C7: PC Ultra，2025首发窗口；结构/动画辅以预设未明的PC评测 | E7: 2025-10 v1.2.1另有主机模式与性能调整；本行不是2026当前PS5结论。 | F7: 最接近的系列重制参照；优先看场景、材质、光照与动作融合。 | G7: D-CB1 / D-CB2 / DELTA_DSO / DELTA_GR / D-K2 / D-K3
A8: 黑神话：悟空 | B8: 2024｜UE5｜已发售 | C8: PC高端样本组合，2024-08；D/E/F采用Full RT Ultra，J采用DLSS；非单机统一预设实测 | E8: 2025-10 PS5新增原生60Hz性能选项；旧PS5帧生成分析不能代表当前版本。 | F8: 动作游戏参照；看光照、阴影、反射与战斗特效，另查运动清晰度。 | G8: WK_DF_PC_FULL / WK_DSO_PC / WK_CB1 / WK_CB2 / WK_CB3 / WK_CB4 / WK_PATCH_2025
A9: 地狱之刃2：塞娜的史诗 | B9: 2024｜UE5｜已发售 | C9: Xbox Series X，2024原版30fps；不能视为PS5 Enhanced实测 | E9: 2025-08 Enhanced登陆PS5并加入新模式；本表保留证据更完整的原版Xbox样本。 | F9: 角色、自然光、大气与整体电影感上限；受控玩法负荷不等于高速群战预算。 | G9: HB_DF_FULL_2024 / HB_INTERVIEW / HB_ENHANCED_OFFICIAL
A10: 寂静岭2重制版 | B10: 2024｜UE5｜已发售 | C10: 基础PS5，品质模式30fps，2024首发；模式未明的同平台评测只辅助美术判断 | E10: 补丁编号未核实；保留首发档案，不能据此断言最新版本仍有同样缺陷。 | F10: 暗部光照、潮湿反射、雾与空间气氛；高速战斗另评。 | G10: SH_DF / SH_PS / SH_TR
A11: 恶魔之魂重制版 | B11: 2020｜非UE｜历史例外 | C11: 基础PS5，品质模式4K/30fps，2020首发；模式未明的观察只作辅助 | E11: Bluepoint Engine；不满足2022之后UE条件，单列作历史完成度参考。 | F11: 验证传统技术也能形成成熟光色、材质和特效；不以引擎代际直接评级。 | G11: DS_ARS / DS_GS / DS_VGC / DS_GDC
A12: 影之刃零（待发售） | B12: 2026计划｜UE5｜未发售 | C12: 截至2026-10-12未发售；2025 Gamescom PC最高+RT演示只作观察 | E12: 官方计划2026-10-29发售（部分地区10-28）；演示不代表PS5终版商品。 | F12: 保留动作、衣物、刀光、命中反馈观察席位，终版推出后填分。 | G12: P-PS26 / P-PS23 / P-DF
A15: 分值 / 5 | B15: 沿用的含义 | C15: 桌面初评如何使用
A16: 0 | B16: 严重失效 | C16: 仅有实证时记0；缺数据留空。
A17: 1 | B17: 明显落后 | C17: 常态游玩中明显损害可信度或辨识。
A18: 2 | B18: 低于基本合格 | C18: 有表现但常见镜头缺陷明显。
A19: 3 | B19: 基本合格 | C19: 主要视觉目标成立，缺陷仍可见。
A20: 4 | B20: 高品质 | C20: 多数游玩场景表现稳定，缺陷较轻。
A21: 5 | B21: 旗舰候选 | C21: 初评区间上沿代表需现场验证的旗舰水准；正式5分须压力验收。
A24: 计算 / 规则 | B24: 定义 | C24: 使用限制
A25: 单项参考区间 | B25: 0–5区间，由原始观察映射到本项目尺度 | C25: 区间不是统计置信区间，0.5分为粗粒度判断。没有把媒体综合评分除以10。
A26: 视觉基础指数 | B26: A、B、C、D、H五类，原权重合计52，再归一至100 | C26: 只衡量构图、场景、材质、灯光、角色；不能叫作全商品总分。
A27: 指数公式 | B27: Σ(五类分数×原权重) ÷ 5 ÷ 52 × 100 | C27: 上下沿分别计算；五类全部有分才显示。重叠区间不排先后。
A28: 桌面全维度区间 | B28: Σ(12类分数×原权重) ÷ 5 | C28: 12类都有初评才显示。即使有区间，仍未完成60项实机验收。
A29: 类别覆盖权重 | B29: 已提供区间的类别原权重之和 ÷ 100 | C29: 仅表示桌面资料涉及哪些类目，不是60项证据完整率。
A30: 本项目类别分 | B30: 把原60项表同类别的5个合成分取平均，填入黄色格 | C30: 合成分沿用典型70%＋压力30%。不要以单张最佳截图代替。
A31: 本项目加分空间 | B31: MAX(0,目标类别分－本项目类别分) ÷ 5 × 类别权重 | C31: 只是分值收益；需结合GPU成本、制作工时及修复依赖决定顺序。
A32: 跨平台对标 | B32: PC、Xbox与PS5分别标明，只比较视觉完成度方向 | C32: 基础PS5性能承诺必须用基础PS5同Build、同模式实测。
A33: 帧率选择 | B33: 60 / 40 / 30分别对应约16.67 / 25.00 / 33.33毫秒 | C33: 40模式还须说明120Hz显示条件；帧生成与实际渲染帧率分开记录。
A34: 正式商品评级 | B34: 使用原60项表及门槛，80为建议高品质目标，85为争取值 | C34: 这些是项目内部建议线，不是行业认证，也不是未来市场保证。
A37: 先补的数据 | B37: 要解决的问题 | C37: 建议采样
... A43: 同场景60 / 40 / 30画质方案 | B43: 落实总监允许降低60fps优先度的决定 | C43: 记录每项画质收益、响应、最低帧、帧时间和显存成本。
