Workbook

Sheet 总览
A2: 写实动作游戏产品美术评审
A4: 项目 | B4: 合金装备复仇重制（工作名） | E4: Build
A5: 评测日期 | E5: 评测人
A6: 目标FPS | B6: 60 | E6: 输出 / 重建
A8: 视觉总分 | B8: =IF(AND(B10=60,F10=60),ROUND(SUM('评分录入'!H6:H65),6),"") | E8: 分数段等级 | F8: =IF(ISNUMBER(B8),LOOKUP(B8,'使用说明'!$A$23:$A$27,'使用说明'!$B$23:$B$27),"")
A9: 评测状态 | B9: =IF(B10<60,"待补评分",IF(F10<60,"待补证据","评分与证据齐全")) -> 待补评分 | E9: 性能及响应 | F9: 待验证
A10: 评分完成 | B10: =SUM('评分录入'!P6:P65) -> 0 | E10: 证据完整 | F10: =SUM('评分录入'!Q6:Q65) -> 0
A11: 评分覆盖 | B11: =SUMPRODUCT('评分录入'!D6:D65,'评分录入'!P6:P65)/100 -> 0 | E11: 证据覆盖 | F11: =SUMPRODUCT('评分录入'!D6:D65,'评分录入'!Q6:Q65)/100 -> 0
A13: 维度 | B13: 评审范围 | C13: 权重 | D13: 评分完成 | E13: 证据完整 | F13: 维度分 / 5 | G13: 分数贡献 | H13: 到4分的分差
A14: A | B14: 整体视觉设计 | C14: 6 | D14: =SUMIFS('评分录入'!$P$6:$P$65,'评分录入'!$B$6:$B$65,B14) -> 0 | E14: =SUMIFS('评分录入'!$Q$6:$Q$65,'评分录入'!$B$6:$B$65,B14) -> 0 | F14: =IF(D14=5,ROUND(SUMIFS('评分录入'!$H$6:$H$65,'评分录入'!$B$6:$B$65,B14)/C14*5,6),"") | G14: =IF(D14=5,SUMIFS('评分录入'!$H$6:$H$65,'评分录入'!$B$6:$B$65,B14),"") | H14: =IF(ISNUMBER(F14),MAX(0,(4-F14)/5*C14),"")
A15: B | B15: 场景与几何 | C15: 12 | D15: =SUMIFS('评分录入'!$P$6:$P$65,'评分录入'!$B$6:$B$65,B15) -> 0 | E15: =SUMIFS('评分录入'!$Q$6:$Q$65,'评分录入'!$B$6:$B$65,B15) -> 0 | F15: =IF(D15=5,ROUND(SUMIFS('评分录入'!$H$6:$H$65,'评分录入'!$B$6:$B$65,B15)/C15*5,6),"") | G15: =IF(D15=5,SUMIFS('评分录入'!$H$6:$H$65,'评分录入'!$B$6:$B$65,B15),"") | H15: =IF(ISNUMBER(F15),MAX(0,(4-F15)/5*C15),"")
A16: C | B16: 材质与纹理 | C16: 10 | D16: =SUMIFS('评分录入'!$P$6:$P$65,'评分录入'!$B$6:$B$65,B16) -> 0 | E16: =SUMIFS('评分录入'!$Q$6:$Q$65,'评分录入'!$B$6:$B$65,B16) -> 0 | F16: =IF(D16=5,ROUND(SUMIFS('评分录入'!$H$6:$H$65,'评分录入'!$B$6:$B$65,B16)/C16*5,6),"") | G16: =IF(D16=5,SUMIFS('评分录入'!$H$6:$H$65,'评分录入'!$B$6:$B$65,B16),"") | H16: =IF(ISNUMBER(F16),MAX(0,(4-F16)/5*C16),"")
A17: D | B17: 灯光与间接光 | C17: 14 | D17: =SUMIFS('评分录入'!$P$6:$P$65,'评分录入'!$B$6:$B$65,B17) -> 0 | E17: =SUMIFS('评分录入'!$Q$6:$Q$65,'评分录入'!$B$6:$B$65,B17) -> 0 | F17: =IF(D17=5,ROUND(SUMIFS('评分录入'!$H$6:$H$65,'评分录入'!$B$6:$B$65,B17)/C17*5,6),"") | G17: =IF(D17=5,SUMIFS('评分录入'!$H$6:$H$65,'评分录入'!$B$6:$B$65,B17),"") | H17: =IF(ISNUMBER(F17),MAX(0,(4-F17)/5*C17),"")
A18: E | B18: 阴影与接触关系 | C18: 8 | D18: =SUMIFS('评分录入'!$P$6:$P$65,'评分录入'!$B$6:$B$65,B18) -> 0 | E18: =SUMIFS('评分录入'!$Q$6:$Q$65,'评分录入'!$B$6:$B$65,B18) -> 0 | F18: =IF(D18=5,ROUND(SUMIFS('评分录入'!$H$6:$H$65,'评分录入'!$B$6:$B$65,B18)/C18*5,6),"") | G18: =IF(D18=5,SUMIFS('评分录入'!$H$6:$H$65,'评分录入'!$B$6:$B$65,B18),"") | H18: =IF(ISNUMBER(F18),MAX(0,(4-F18)/5*C18),"")
A19: F | B19: 反射与环境照明输入 | C19: 6 | D19: =SUMIFS('评分录入'!$P$6:$P$65,'评分录入'!$B$6:$B$65,B19) -> 0 | E19: =SUMIFS('评分录入'!$Q$6:$Q$65,'评分录入'!$B$6:$B$65,B19) -> 0 | F19: =IF(D19=5,ROUND(SUMIFS('评分录入'!$H$6:$H$65,'评分录入'!$B$6:$B$65,B19)/C19*5,6),"") | G19: =IF(D19=5,SUMIFS('评分录入'!$H$6:$H$65,'评分录入'!$B$6:$B$65,B19),"") | H19: =IF(ISNUMBER(F19),MAX(0,(4-F19)/5*C19),"")
A20: G | B20: 大气与雾 | C20: 5 | D20: =SUMIFS('评分录入'!$P$6:$P$65,'评分录入'!$B$6:$B$65,B20) -> 0 | E20: =SUMIFS('评分录入'!$Q$6:$Q$65,'评分录入'!$B$6:$B$65,B20) -> 0 | F20: =IF(D20=5,ROUND(SUMIFS('评分录入'!$H$6:$H$65,'评分录入'!$B$6:$B$65,B20)/C20*5,6),"") | G20: =IF(D20=5,SUMIFS('评分录入'!$H$6:$H$65,'评分录入'!$B$6:$B$65,B20),"") | H20: =IF(ISNUMBER(F20),MAX(0,(4-F20)/5*C20),"")
A21: H | B21: 角色与动作呈现 | C21: 10 | D21: =SUMIFS('评分录入'!$P$6:$P$65,'评分录入'!$B$6:$B$65,B21) -> 0 | E21: =SUMIFS('评分录入'!$Q$6:$Q$65,'评分录入'!$B$6:$B$65,B21) -> 0 | F21: =IF(D21=5,ROUND(SUMIFS('评分录入'!$H$6:$H$65,'评分录入'!$B$6:$B$65,B21)/C21*5,6),"") | G21: =IF(D21=5,SUMIFS('评分录入'!$H$6:$H$65,'评分录入'!$B$6:$B$65,B21),"") | H21: =IF(ISNUMBER(F21),MAX(0,(4-F21)/5*C21),"")
A22: I | B22: 特效与战斗反馈 | C22: 8 | D22: =SUMIFS('评分录入'!$P$6:$P$65,'评分录入'!$B$6:$B$65,B22) -> 0 | E22: =SUMIFS('评分录入'!$Q$6:$Q$65,'评分录入'!$B$6:$B$65,B22) -> 0 | F22: =IF(D22=5,ROUND(SUMIFS('评分录入'!$H$6:$H$65,'评分录入'!$B$6:$B$65,B22)/C22*5,6),"") | G22: =IF(D22=5,SUMIFS('评分录入'!$H$6:$H$65,'评分录入'!$B$6:$B$65,B22),"") | H22: =IF(ISNUMBER(F22),MAX(0,(4-F22)/5*C22),"")
A23: J | B23: 运动画质与重建 | C23: 10 | D23: =SUMIFS('评分录入'!$P$6:$P$65,'评分录入'!$B$6:$B$65,B23) -> 0 | E23: =SUMIFS('评分录入'!$Q$6:$Q$65,'评分录入'!$B$6:$B$65,B23) -> 0 | F23: =IF(D23=5,ROUND(SUMIFS('评分录入'!$H$6:$H$65,'评分录入'!$B$6:$B$65,B23)/C23*5,6),"") | G23: =IF(D23=5,SUMIFS('评分录入'!$H$6:$H$65,'评分录入'!$B$6:$B$65,B23),"") | H23: =IF(ISNUMBER(F23),MAX(0,(4-F23)/5*C23),"")
A24: K | B24: 后期与显示 | C24: 6 | D24: =SUMIFS('评分录入'!$P$6:$P$65,'评分录入'!$B$6:$B$65,B24) -> 0 | E24: =SUMIFS('评分录入'!$Q$6:$Q$65,'评分录入'!$B$6:$B$65,B24) -> 0 | F24: =IF(D24=5,ROUND(SUMIFS('评分录入'!$H$6:$H$65,'评分录入'!$B$6:$B$65,B24)/C24*5,6),"") | G24: =IF(D24=5,SUMIFS('评分录入'!$H$6:$H$65,'评分录入'!$B$6:$B$65,B24),"") | H24: =IF(ISNUMBER(F24),MAX(0,(4-F24)/5*C24),"")
A25: L | B25: 全流程一致性 | C25: 5 | D25: =SUMIFS('评分录入'!$P$6:$P$65,'评分录入'!$B$6:$B$65,B25) -> 0 | E25: =SUMIFS('评分录入'!$Q$6:$Q$65,'评分录入'!$B$6:$B$65,B25) -> 0 | F25: =IF(D25=5,ROUND(SUMIFS('评分录入'!$H$6:$H$65,'评分录入'!$B$6:$B$65,B25)/C25*5,6),"") | G25: =IF(D25=5,SUMIFS('评分录入'!$H$6:$H$65,'评分录入'!$B$6:$B$65,B25),"") | H25: =IF(ISNUMBER(F25),MAX(0,(4-F25)/5*C25),"")
A26: 合计 | C26: 100 | D26: =B10 -> 0 | E26: =F10 -> 0 | G26: =IF(ISNUMBER(B8),B8,"")
A28: 平台 | B28: 基础PS5 | E28: 关键缺陷审查 | F28: 待验证
A29: 产品验收 | B29: =IF(OR(F9="不通过",F28="不通过"),"不通过",IF(F29="待评","待评",IF(F29="未达底线","不通过",IF(AND(F9="通过",F28="通过"),"通过","待验证")))) -> 待评 | E29: 视觉底线 | F29: {=IF(NOT(ISNUMBER(B8)),"待评",IF(AND(B8>=80,F17>=4,F23>=4,F15>=3.5,F16>=3.5,F18>=3.5,F21>=3.5,INDEX('评分录入'!$F$6:$F$65,MATCH("I1",'评分录入'!$A$6:$A$65,0))>=4,MIN('评分录入'!G6:G65)>=3),"达到底线","未达底线"))} -> 待评
A31: 领先认定 | B31: =IF(NOT(ISNUMBER(B8)),"待评",IF(B8<90,"未达90分",IF(MIN(F14:F25)<4,"维度底线未满足",IF(B29="通过","满足领先建议线",IF(B29="不通过","验收未通过","待审查"))))) -> 待评
A33: 每种30/40/60 FPS模式单独评测。视觉分与性能分开，验收需同时达到视觉底线及所选模式性能。
A35: 黄色为录入区。总分空白表示资料不足。各维度5项；同维度内等权；满分贡献合计100分。
A37: 高品质底线：D/J≥4，B/C/E/H≥3.5，I1压力分≥4，全部单项合成≥3，且视觉总分≥80。
A39: 所有等级为内部建议标准。先以统一Build实机对标校准，30/40/60 FPS与动作响应条件由项目共同定版。
A41: 计划增分 | B41: =IF(COUNT('评分录入'!R6:R65)=0,"",SUM('评分录入'!R6:R65)) | E41: 目标模拟分 | F41: =IF(AND(ISNUMBER(B8),ISNUMBER(B41)),B8+B41,"")
A43: 在评分录入O列填写目标，可模拟所选改进项的增分。模拟值需在对应模式重测兑现，不作为验收证据。

Sheet 评分录入
A2: 评分录入
A4: 黄色单元格为录入区。典型与压力评分均为0–5。0是实际不合格，空白是尚未评测。只有两项均有效才计算合成分。
A5: 编号 | B5: 维度 | C5: 指标 | D5: 满分贡献 | E5: 典型评分 | F5: 压力评分 | G5: 合成分 / 5 | H5: 得分贡献 | I5: 双场景核验 | J5: 典型场景证据 | K5: 压力场景证据 | L5: Build / 机位 | M5: 缺陷与修复动作 | N5: 负责人 | O5: 目标分 / 5 | P5: 评分完整 | Q5: 证据完整 | R5: 目标增分
A6: A1 | B6: 整体视觉设计 | C6: 视觉语言统一 | D6: {=INDEX('60项标准'!$D$6:$D$65,MATCH(A6,'60项标准'!$A$6:$A$65,0))} -> 1.2 | G6: =IF(P6=1,ROUND(E6*'使用说明'!$B$5+F6*'使用说明'!$B$6,6),"") | H6: =IF(P6=1,G6/5*D6,"") | P6: =IF(COUNT(E6:F6)<>2,0,IF(AND(MIN(E6:F6)>=0,MAX(E6:F6)<=5),1,0)) -> 0 | Q6: =IF(AND(I6="已核验",J6<>"",K6<>"",L6<>""),1,0) -> 0 | R6: =IF(AND(P6=1,ISNUMBER(O6),O6>=0,O6<=5),(O6-G6)/5*D6,"")
A7: A2 | B7: 整体视觉设计 | C7: 构图与主次 | D7: {=INDEX('60项标准'!$D$6:$D$65,MATCH(A7,'60项标准'!$A$6:$A$65,0))} -> 1.2 | G7: =IF(P7=1,ROUND(E7*'使用说明'!$B$5+F7*'使用说明'!$B$6,6),"") | H7: =IF(P7=1,G7/5*D7,"") | P7: =IF(COUNT(E7:F7)<>2,0,IF(AND(MIN(E7:F7)>=0,MAX(E7:F7)<=5),1,0)) -> 0 | Q7: =IF(AND(I7="已核验",J7<>"",K7<>"",L7<>""),1,0) -> 0 | R7: =IF(AND(P7=1,ISNUMBER(O7),O7>=0,O7<=5),(O7-G7)/5*D7,"")
A8: A3 | B8: 整体视觉设计 | C8: 空间与地标 | D8: {=INDEX('60项标准'!$D$6:$D$65,MATCH(A8,'60项标准'!$A$6:$A$65,0))} -> 1.2 | G8: =IF(P8=1,ROUND(E8*'使用说明'!$B$5+F8*'使用说明'!$B$6,6),"") | H8: =IF(P8=1,G8/5*D8,"") | P8: =IF(COUNT(E8:F8)<>2,0,IF(AND(MIN(E8:F8)>=0,MAX(E8:F8)<=5),1,0)) -> 0 | Q8: =IF(AND(I8="已核验",J8<>"",K8<>"",L8<>""),1,0) -> 0 | R8: =IF(AND(P8=1,ISNUMBER(O8),O8>=0,O8<=5),(O8-G8)/5*D8,"")
A9: A4 | B9: 整体视觉设计 | C9: 色彩与明暗组织 | D9: {=INDEX('60项标准'!$D$6:$D$65,MATCH(A9,'60项标准'!$A$6:$A$65,0))} -> 1.2 | G9: =IF(P9=1,ROUND(E9*'使用说明'!$B$5+F9*'使用说明'!$B$6,6),"") | H9: =IF(P9=1,G9/5*D9,"") | P9: =IF(COUNT(E9:F9)<>2,0,IF(AND(MIN(E9:F9)>=0,MAX(E9:F9)<=5),1,0)) -> 0 | Q9: =IF(AND(I9="已核验",J9<>"",K9<>"",L9<>""),1,0) -> 0 | R9: =IF(AND(P9=1,ISNUMBER(O9),O9>=0,O9<=5),(O9-G9)/5*D9,"")
A10: A5 | B10: 整体视觉设计 | C10: 重制的现代呈现 | D10: {=INDEX('60项标准'!$D$6:$D$65,MATCH(A10,'60项标准'!$A$6:$A$65,0))} -> 1.2 | G10: =IF(P10=1,ROUND(E10*'使用说明'!$B$5+F10*'使用说明'!$B$6,6),"") | H10: =IF(P10=1,G10/5*D10,"") | P10: =IF(COUNT(E10:F10)<>2,0,IF(AND(MIN(E10:F10)>=0,MAX(E10:F10)<=5),1,0)) -> 0 | Q10: =IF(AND(I10="已核验",J10<>"",K10<>"",L10<>""),1,0) -> 0 | R10: =IF(AND(P10=1,ISNUMBER(O10),O10>=0,O10<=5),(O10-G10)/5*D10,"")
A11: B1 | B11: 场景与几何 | C11: 尺度与轮廓 | D11: {=INDEX('60项标准'!$D$6:$D$65,MATCH(A11,'60项标准'!$A$6:$A$65,0))} -> 2.4 | G11: =IF(P11=1,ROUND(E11*'使用说明'!$B$5+F11*'使用说明'!$B$6,6),"") | H11: =IF(P11=1,G11/5*D11,"") | P11: =IF(COUNT(E11:F11)<>2,0,IF(AND(MIN(E11:F11)>=0,MAX(E11:F11)<=5),1,0)) -> 0 | Q11: =IF(AND(I11="已核验",J11<>"",K11<>"",L11<>""),1,0) -> 0 | R11: =IF(AND(P11=1,ISNUMBER(O11),O11>=0,O11<=5),(O11-G11)/5*D11,"")
A12: B2 | B12: 场景与几何 | C12: 结构与连接 | D12: {=INDEX('60项标准'!$D$6:$D$65,MATCH(A12,'60项标准'!$A$6:$A$65,0))} -> 2.4 | G12: =IF(P12=1,ROUND(E12*'使用说明'!$B$5+F12*'使用说明'!$B$6,6),"") | H12: =IF(P12=1,G12/5*D12,"") | P12: =IF(COUNT(E12:F12)<>2,0,IF(AND(MIN(E12:F12)>=0,MAX(E12:F12)<=5),1,0)) -> 0 | Q12: =IF(AND(I12="已核验",J12<>"",K12<>"",L12<>""),1,0) -> 0 | R12: =IF(AND(P12=1,ISNUMBER(O12),O12>=0,O12<=5),(O12-G12)/5*D12,"")
A13: B3 | B13: 场景与几何 | C13: 密度与重复控制 | D13: {=INDEX('60项标准'!$D$6:$D$65,MATCH(A13,'60项标准'!$A$6:$A$65,0))} -> 2.4 | G13: =IF(P13=1,ROUND(E13*'使用说明'!$B$5+F13*'使用说明'!$B$6,6),"") | H13: =IF(P13=1,G13/5*D13,"") | P13: =IF(COUNT(E13:F13)<>2,0,IF(AND(MIN(E13:F13)>=0,MAX(E13:F13)<=5),1,0)) -> 0 | Q13: =IF(AND(I13="已核验",J13<>"",K13<>"",L13<>""),1,0) -> 0 | R13: =IF(AND(P13=1,ISNUMBER(O13),O13>=0,O13<=5),(O13-G13)/5*D13,"")
A14: B4 | B14: 场景与几何 | C14: 场景融合与叙事 | D14: {=INDEX('60项标准'!$D$6:$D$65,MATCH(A14,'60项标准'!$A$6:$A$65,0))} -> 2.4 | G14: =IF(P14=1,ROUND(E14*'使用说明'!$B$5+F14*'使用说明'!$B$6,6),"") | H14: =IF(P14=1,G14/5*D14,"") | P14: =IF(COUNT(E14:F14)<>2,0,IF(AND(MIN(E14:F14)>=0,MAX(E14:F14)<=5),1,0)) -> 0 | Q14: =IF(AND(I14="已核验",J14<>"",K14<>"",L14<>""),1,0) -> 0 | R14: =IF(AND(P14=1,ISNUMBER(O14),O14>=0,O14<=5),(O14-G14)/5*D14,"")
A15: B5 | B15: 场景与几何 | C15: 距离与流送完整性 | D15: {=INDEX('60项标准'!$D$6:$D$65,MATCH(A15,'60项标准'!$A$6:$A$65,0))} -> 2.4 | G15: =IF(P15=1,ROUND(E15*'使用说明'!$B$5+F15*'使用说明'!$B$6,6),"") | H15: =IF(P15=1,G15/5*D15,"") | P15: =IF(COUNT(E15:F15)<>2,0,IF(AND(MIN(E15:F15)>=0,MAX(E15:F15)<=5),1,0)) -> 0 | Q15: =IF(AND(I15="已核验",J15<>"",K15<>"",L15<>""),1,0) -> 0 | R15: =IF(AND(P15=1,ISNUMBER(O15),O15>=0,O15<=5),(O15-G15)/5*D15,"")
A16: C1 | B16: 材质与纹理 | C16: PBR响应与物质区分 | D16: {=INDEX('60项标准'!$D$6:$D$65,MATCH(A16,'60项标准'!$A$6:$A$65,0))} -> 2 | G16: =IF(P16=1,ROUND(E16*'使用说明'!$B$5+F16*'使用说明'!$B$6,6),"") | H16: =IF(P16=1,G16/5*D16,"") | P16: =IF(COUNT(E16:F16)<>2,0,IF(AND(MIN(E16:F16)>=0,MAX(E16:F16)<=5),1,0)) -> 0 | Q16: =IF(AND(I16="已核验",J16<>"",K16<>"",L16<>""),1,0) -> 0 | R16: =IF(AND(P16=1,ISNUMBER(O16),O16>=0,O16<=5),(O16-G16)/5*D16,"")
A17: C2 | B17: 材质与纹理 | C17: 纹理的有效清晰度 | D17: {=INDEX('60项标准'!$D$6:$D$65,MATCH(A17,'60项标准'!$A$6:$A$65,0))} -> 2 | G17: =IF(P17=1,ROUND(E17*'使用说明'!$B$5+F17*'使用说明'!$B$6,6),"") | H17: =IF(P17=1,G17/5*D17,"") | P17: =IF(COUNT(E17:F17)<>2,0,IF(AND(MIN(E17:F17)>=0,MAX(E17:F17)<=5),1,0)) -> 0 | Q17: =IF(AND(I17="已核验",J17<>"",K17<>"",L17<>""),1,0) -> 0 | R17: =IF(AND(P17=1,ISNUMBER(O17),O17>=0,O17<=5),(O17-G17)/5*D17,"")
... A65: L5 | B65: 全流程一致性 | C65: 模式与版本一致性 | D65: {=INDEX('60项标准'!$D$6:$D$65,MATCH(A65,'60项标准'!$A$6:$A$65,0))} -> 1 | G65: =IF(P65=1,ROUND(E65*'使用说明'!$B$5+F65*'使用说明'!$B$6,6),"") | H65: =IF(P65=1,G65/5*D65,"") | P65: =IF(COUNT(E65:F65)<>2,0,IF(AND(MIN(E65:F65)>=0,MAX(E65:F65)<=5),1,0)) -> 0 | Q65: =IF(AND(I65="已核验",J65<>"",K65<>"",L65<>""),1,0) -> 0 | R65: =IF(AND(P65=1,ISNUMBER(O65),O65>=0,O65<=5),(O65-G65)/5*D65,"")

Sheet 60项标准
A2: 写实动作游戏美术标准（60项）
A4: 3分为基本合格。4分为高品质商品线。5分需在压力场景保持同等完成度。技术方案与参数本身不直接得分。
A5: 编号 | B5: 维度 | C5: 指标 | D5: 满分贡献 | E5: 3分：基本合格 | F5: 4分：高品质 | G5: 5分：旗舰表现 | H5: 应提交的证据 | I5: 优先改进方向 | J5: 参考来源
A6: A1 | B6: 整体视觉设计 | C6: 视觉语言统一 | D6: 1.2 | E6: 同一关卡色彩、比例、工业设计无明显冲突 | F6: 跨关卡保持一致，重点区域有明确差异 | G6: 整体辨识度强且细节持续服务主题 | H6: 风格规范；各章节固定镜头接触表 | I6: 针对“视觉语言统一”记录典型和压力缺陷，优先修复影响游玩及画面可信度的问题。 | J6: 项目内部建议标准；技术机制依据见配套报告
A7: A2 | B7: 整体视觉设计 | C7: 构图与主次 | D7: 1.2 | E7: 常用视角主体与背景能分开 | F7: 移动、锁定及高密度战斗时主次稳定 | G7: 复杂场景仍能自然引导注意力且有观赏性 | H7: 正常/压力战斗录像；目标识别测试 | I7: 针对“构图与主次”记录典型和压力缺陷，优先修复影响游玩及画面可信度的问题。 | J7: 项目内部建议标准；技术机制依据见配套报告
A8: A3 | B8: 整体视觉设计 | C8: 空间与地标 | D8: 1.2 | E8: 路径、地标、战斗空间可辨识 | F8: 相似场景也能通过构图与光色建立记忆点 | G8: 空间叙事与玩法形成连续且独特的视觉体验 | H8: 关卡路线；迷路及误识别记录 | I8: 针对“空间与地标”记录典型和压力缺陷，优先修复影响游玩及画面可信度的问题。 | J8: 项目内部建议标准；技术机制依据见配套报告
A9: A4 | B9: 整体视觉设计 | C9: 色彩与明暗组织 | D9: 1.2 | E9: 无大面积无意死黑、过曝或全灰 | F9: 光色变化支持节奏，敌人轮廓稳定 | G9: 克制且丰富的明暗层次贯穿全流程 | H9: 各场景亮度/色彩截图；曝光配置 | I9: 针对“色彩与明暗组织”记录典型和压力缺陷，优先修复影响游玩及画面可信度的问题。 | J9: 项目内部建议标准；技术机制依据见配套报告
A10: A5 | B10: 整体视觉设计 | C10: 重制的现代呈现 | D10: 1.2 | E10: 保留IP辨识且无明显时代不一致元素 | F10: 经典场景在比例、照明、材质上得到统一重构 | G10: 现代细节与原作气质融合，有自身标志性镜头 | H10: 原作对应镜头；重制美术意图说明 | I10: 针对“重制的现代呈现”记录典型和压力缺陷，优先修复影响游玩及画面可信度的问题。 | J10: 项目内部建议标准；技术机制依据见配套报告
A11: B1 | B11: 场景与几何 | C11: 尺度与轮廓 | D11: 2.4 | E11: 门、台阶、结构和人物比例可信 | F11: 常见距离下曲面、倒角与重要轮廓完整 | G11: 近中远景轮廓均精致且服务构图 | H11: 游戏相机近中远景；几何/LOD说明 | I11: 针对“尺度与轮廓”记录典型和压力缺陷，优先修复影响游玩及画面可信度的问题。 | J11: 项目内部建议标准；技术机制依据见配套报告
A12: B2 | B12: 场景与几何 | C12: 结构与连接 | D12: 2.4 | E12: 墙地交界、设备支撑和建筑连接合理 | F12: 遮挡背后及次要路径也无明显拼装穿帮 | G12: 结构层级、受力逻辑与功能细节高度可信 | H12: 正常路线及极端机位；问题坐标 | I12: 针对“结构与连接”记录典型和压力缺陷，优先修复影响游玩及画面可信度的问题。 | J12: 项目内部建议标准；技术机制依据见配套报告
A13: B3 | B13: 场景与几何 | C13: 密度与重复控制 | D13: 2.4 | E13: 正常路线不显著空洞或重复铺排 | F13: 大中小细节有层级，重复纹理与模块被有效化解 | G13: 密度随叙事与战斗节奏变化，持续保持差异性 | H13: 章节抽样；重复模块分布；屏幕占比 | I13: 针对“密度与重复控制”记录典型和压力缺陷，优先修复影响游玩及画面可信度的问题。 | J13: 项目内部建议标准；技术机制依据见配套报告
A14: B4 | B14: 场景与几何 | C14: 场景融合与叙事 | D14: 2.4 | E14: 植被/碎屑/损伤/污迹符合环境 | F14: 接地过渡自然，使用与破坏痕迹形成逻辑 | G14: 可探索细节丰富但不造成视觉噪声 | H14: 地面过渡、贴花、磨损和环境故事样例 | I14: 针对“场景融合与叙事”记录典型和压力缺陷，优先修复影响游玩及画面可信度的问题。 | J14: 项目内部建议标准；技术机制依据见配套报告
A15: B5 | B15: 场景与几何 | C15: 距离与流送完整性 | D15: 2.4 | E15: 正常路线无明显空洞、物体突现 | F15: 快跑回头及场景切换下几何细节保持连续 | G15: 高压移动及长视距下仍无引人注意的切换 | H15: Nanite/LOD/HLOD与裁剪配置；冷/热跑录像 | I15: 针对“距离与流送完整性”记录典型和压力缺陷，优先修复影响游玩及画面可信度的问题。 | J15: 项目内部建议标准；技术机制依据见配套报告
A16: C1 | B16: 材质与纹理 | C16: PBR响应与物质区分 | D16: 2 | E16: 金属、漆、塑料、石材对光反应可区分 | F16: 不同光照下仍可信，无普遍塑料感 | G16: 复杂复合材质有细腻且稳定的能量与层次感 | H16: BaseColor/Roughness/Metallic视图；材质样本 | I16: 针对“PBR响应与物质区分”记录典型和压力缺陷，优先修复影响游玩及画面可信度的问题。 | J16: 项目内部建议标准；技术机制依据见配套报告
A17: C2 | B17: 材质与纹理 | C17: 纹理的有效清晰度 | D17: 2 | E17: 正常游戏距离主体不糊，密度无突兀落差 | F17: 近景与掠射角细节充分且无过度锐化 | G17: 主要观察距离细节丰富且移动中可持续辨认 | H17: 源/导入/驻留mip；Texel密度；各向异性设置 | I17: 针对“纹理的有效清晰度”记录典型和压力缺陷，优先修复影响游玩及画面可信度的问题。 | J17: 项目内部建议标准；技术机制依据见配套报告
... A65: L5 | B65: 全流程一致性 | C65: 模式与版本一致性 | D65: 1 | E65: 提交评审的版本、模式可复现 | F65: 宣传关键镜头与承诺模式差异透明且可解释 | G65: 常态游玩也能持续兑现宣传的核心视觉特征 | H65: 版本号；平台模式矩阵；宣传/实机配对 | I65: 针对“模式与版本一致性”记录典型和压力缺陷，优先修复影响游玩及画面可信度的问题。 | J65: 项目内部建议标准；技术机制依据见配套报告

Sheet 补数清单
A2: 补数清单
A4: 先索取同一Build的PS5实机录屏和性能记录，再做开关对照与参数核验。负责人确认事实后，由评审人在评分录入页给分。
A5: 编号 | B5: 维度 | C5: 指标 | D5: 需提交的数据 / 证据 | E5: 已知事实 | F5: 待确认问题 | G5: 负责人 | H5: 最新测量结果 | I5: 证据链接 | J5: Build / 测量日期 | K5: 收集状态
A6: A1 | B6: 整体视觉设计 | C6: 视觉语言统一 | D6: 风格规范；各章节固定镜头接触表
A7: A2 | B7: 整体视觉设计 | C7: 构图与主次 | D7: 正常/压力战斗录像；目标识别测试
A8: A3 | B8: 整体视觉设计 | C8: 空间与地标 | D8: 关卡路线；迷路及误识别记录
A9: A4 | B9: 整体视觉设计 | C9: 色彩与明暗组织 | D9: 各场景亮度/色彩截图；曝光配置
A10: A5 | B10: 整体视觉设计 | C10: 重制的现代呈现 | D10: 原作对应镜头；重制美术意图说明
A11: B1 | B11: 场景与几何 | C11: 尺度与轮廓 | D11: 游戏相机近中远景；几何/LOD说明
A12: B2 | B12: 场景与几何 | C12: 结构与连接 | D12: 正常路线及极端机位；问题坐标
A13: B3 | B13: 场景与几何 | C13: 密度与重复控制 | D13: 章节抽样；重复模块分布；屏幕占比
A14: B4 | B14: 场景与几何 | C14: 场景融合与叙事 | D14: 地面过渡、贴花、磨损和环境故事样例
A15: B5 | B15: 场景与几何 | C15: 距离与流送完整性 | D15: Nanite/LOD/HLOD与裁剪配置；冷/热跑录像
A16: C1 | B16: 材质与纹理 | C16: PBR响应与物质区分 | D16: BaseColor/Roughness/Metallic视图；材质样本
A17: C2 | B17: 材质与纹理 | C17: 纹理的有效清晰度 | D17: 源/导入/驻留mip；Texel密度；各向异性设置
... A24: D4 | B24: 灯光与间接光 | C24: 动态光响应 | D24: 动光/破坏录像；更新延迟；GPU分项
A25: D5 | B25: 灯光与间接光 | C25: 全流程灯光覆盖 | D25: 章节接触表；Lighting质量配置与例外清单 | E25: 用户反馈：为争取60FPS采用相对较低设置；实际PS5配置待补 | F25: 提交所选模式的PS5设备配置、质量分级、项目与运行时CVar覆盖、屏幕百分比和GPU/CPU分项耗时。 | K25: 待补
A26: E1 | B26: 阴影与接触关系 | C26: 角色与物体接地 | D26: 脚底/墙角/斜坡录像；接触阴影方案
A27: E2 | B27: 阴影与接触关系 | C27: 阴影形状与柔度 | D27: 主光和局部灯阴影样例；阴影方法
A28: E3 | B28: 阴影与接触关系 | C28: 小尺度遮蔽 | D28: 实际遮蔽机制说明；匹配机制的A/B | E28: 用户反馈：对方称AO开启，但当前AO调试视图全白；具体路径待核验 | F28: 提交引擎版本、渲染路径、GI与遮蔽机制，以及匹配机制的诊断和脚底/墙角同机位开关对照。 | K28: 待补
A29: E4 | B29: 阴影与接触关系 | C29: 阴影覆盖与漏光 | D29: 阴影距离/分辨率；薄墙及远景录像
A30: E5 | B30: 阴影与接触关系 | C30: 动态阴影稳定性 | D30: VSM/传统阴影诊断；动态缓存失效及耗时
A31: F1 | B31: 反射与环境照明输入 | C31: 关键材质反射 | D31: 典型材质Lit录像；反射路径和质量设置
A32: F2 | B32: 反射与环境照明输入 | C32: 屏幕外与遮挡行为 | D32: SSR/Lumen/捕获混合方案；出屏录像
A33: F3 | B33: 反射与环境照明输入 | C33: 粗糙反射与噪声 | D33: 粗糙度分级测试；去噪/追踪参数
A34: F4 | B34: 反射与环境照明输入 | C34: 天空与HDRI匹配 | D34: HDRI用途/格式/动态范围；SkyLight源类型
A35: F5 | B35: 反射与环境照明输入 | C35: 分辨率与捕获有效性 | D35: 源/运行尺寸；cubemap分辨率；4K/8K受控A/B | E35: 用户反馈：HDRI源图为4K；运行尺寸、用途及采样待核验 | F35: 源图用途是什么？提交源格式/动态范围、导入与驻留mip、SkyLight/反射捕获尺寸，以及同机位4K/8K对照。 | K35: 待补
A36: G1 | B36: 大气与雾 | C36: 远中近空间层次 | D36: 长视距同机位；天气和高度雾参数
A37: G2 | B37: 大气与雾 | C37: 局部分布与高度关系 | D37: 局部雾内容；密度/消光；开关对比
A38: G3 | B38: 大气与雾 | C38: 光照散射与遮挡 | D38: 逆光镜头；灯光体积贡献与阴影
A39: G4 | B39: 大气与雾 | C39: 动态雾质量 | D39: 网格/距离；挥刀闪光及转向录像；GPU耗时 | E39: 用户反馈：体积雾已开启，但观察镜头中变化不明显 | F39: 提交同机位开关对照与快速转镜/动光录像；记录密度、消光、网格/距离、灯光体积贡献和GPU成本。 | K39: 待补
A40: G5 | B40: 大气与雾 | C40: 气氛与可读性平衡 | D40: 战斗可读性录像；雾开关和轮廓对比
A41: H1 | B41: 角色与动作呈现 | C41: 主角和主要敌人外观 | D41: 实机近中景；角色材质/LOD/皮肤或装甲
A42: H2 | B42: 角色与动作呈现 | C42: 角色融入场景 | D42: 穿越多光照区域录像
A43: H3 | B43: 角色与动作呈现 | C43: 变形与动画衔接 | D43: 动作合集；骨骼/布料/附属件配置
A44: H4 | B44: 角色与动作呈现 | C44: 武器与切割破坏 | D44: 切割/断裂录像；碎片上限与退场规则
A45: H5 | B45: 角色与动作呈现 | C45: 角色细节的动态稳定 | D45: 头发/布料/附件近景及压力录像
A46: I1 | B46: 特效与战斗反馈 | C46: 攻击预兆与目标可读 | D46: 最坏战斗录像；设计规定的预兆时间窗
A47: I2 | B47: 特效与战斗反馈 | C47: 命中节奏与力度 | D47: 逐帧命中时序；不同表面命中样例
A48: I3 | B48: 特效与战斗反馈 | C48: 特效材质与空间感 | D48: Niagara/材质设置；深度交界和斜角录像
...

Sheet 使用说明
A2: 使用说明与评分口径
A5: 典型场景权重 | B5: 0.7 | C5: 场景选取需覆盖主要关卡、光照和材质。
A6: 压力场景权重 | B6: 0.3 | C6: 高速转镜、最重战斗、破坏、粒子与场景切换。
A8: 评分值 | B8: 统一含义 | C8: 判断要求
A9: 0 | B9: 严重失效 | C9: 该目标实际失效，明显损害商品体验。禁止用0表示缺失数据。
A10: 1 | B10: 明显落后 | C10: 常态游玩即可发现，破坏可信度、辨识或完整性。
A11: 2 | B11: 低于基本合格 | C11: 功能有表现，但常见镜头缺陷明显，需要重点修复。
A12: 3 | B12: 基本合格 | C12: 典型游玩基本可信。一般缺陷可控，达到该项基本标准。
A13: 4 | B13: 高品质 | C13: 在多数游玩场景稳定达到高品质。缺陷较轻，表现一致。
A14: 5 | B14: 旗舰表现 | C14: 高完成度与动态稳定性兼备，压力场景也经得起检验。
A16: 得分计算 | B16: 公式 | C16: 缺失数据处理
A17: 单项合成分 | B17: 典型 × 70% + 压力 × 30% | C17: 两项有效才计算，评分保留0–5小数。
A18: 单项贡献 | B18: 合成分 ÷ 5 × 满分贡献 | C18: 60项满分贡献合计100。按各维度权重分配。
A19: 证据权重覆盖率 | B19: 已核验项权重合计 ÷ 100 | C19: 双场景已核验且证据、Build/机位齐全。评分覆盖率同样按指标权重统计，完整项数另列。
A20: 正式总分与等级 | B20: 60项评分及证据齐全后判定 | C20: 不足时保持空白。不得将已测少数项目外推为全商品等级。
A22: 最低分 | B22: 等级 | C22: 用于商品评审的含义
A23: 0 | B23: D 低于基础线 | C23: 0–59.9，视觉基础存在明显不足。
A24: 60 | B24: C 基础完成 | C24: 60–69.9，基础完成，但商品竞争力有限。
A25: 70 | B25: B 尚有明显差距 | C25: 70–79.9，距离高品质目标仍有显著短板。
A26: 80 | B26: A 高品质目标 | C26: 80–89.9，另需关键维度、模式性能及缺陷审查通过。
A27: 90 | B27: S 领先分数段 | C27: 90–100，建议全部维度≥4且无关键缺陷才称领先。
A30: 固定评测条件 | B30: 平台 / 模式 / Build | C30: 基础PS5。每种30/40/60 FPS模式单独使用一份评分表。60为优先争取目标，不以非60一票否决。
A31: 证据内容 | B31: 先看最终实机，再看技术解释 | C31: 保留无损截图、正常游玩录屏、同机位A/B对照、GPU与CPU帧时间、缺陷出现频率。
A32: 分辨率与采样 | B32: 不能仅看贴图标称大小 | C32: HDRI要核对用途、动态范围、有效mip、采样与实际反射表现。4K或8K本身不加减分。
A33: AO与雾 | B33: 不能仅看启用开关 | C33: 核验渲染路径与最终空间层次。白色AO视图不能单独证明整体无遮蔽。晴朗低雾不自动扣分。
A34: 对标方式 | B34: 同平台、同模式、同类场景 | C34: 匹配机位、环境复杂度与运动状态。按承诺SDR/HDR支持范围评K5，无HDR不自动低分。
A35: 不适用项 | B35: 评审前固定范围与权重 | C35: 本表默认60项均适用。确实不适用时由总监签字调整标准与权重，再开始评分。禁止写0或临时删除短板。
A36: 标准性质 | B36: 项目评审建议线 v1.0 | C36: 等级与权重是本项目的评审提案。通过首轮实机对标校准，不能宣称为通用行业认证。
A38: 高品质验收底线 | B38: 视觉分≥80 | C38: D灯光、J运动画质≥4。B场景、C材质、E阴影、H角色≥3.5。
A39: 压力与单项底线 | B39: I1压力分≥4 | C39: 所有单项合成分≥3，避免高分掩盖明显短板。
A40: 产品验收状态 | B40: 视觉与性能分开 | C40: 在视觉底线满足后，所选模式性能与动作响应、关键缺陷审查都通过，才显示验收通过。
A41: 90分领先认定 | B41: 分数段与认定分开 | C41: 90分只是数字区间。全部12维度≥4、无关键缺陷、模式性能通过后，才建议认定为领先。
A42: 低帧率模式审查 | B42: 动作响应必须实测 | C42: 40 FPS另核验显示刷新率条件。30 FPS另核验动作响应与动态清晰度，不能只测静态画质。
